Workbook

Sheet Leaves
A1: PELOZDEN RSS INC.
A2: ID NO. | B2: LAST NAME | C2: FIRST NAME | D2: MIDDLE NAME | E2: DATE HIRED | F2: Regularization date | G2: EMPLOYMENT STATUS | H2: Sick Leave | I2: Vacation Leave | J2: Service Incentive Leave | K2: Available Sick Leave | L2: Available Vacation Leave | M2: Available Service Incentive Leave
A3: 0008 | B3: ANTONIO | C3: VINCENT KEVIN | D3: SANTOS | E3: 44796 | F3: =Table1[[#This Row],[DATE HIRED]]+184 -> 44980 | G3: REGULAR
A4: 0011 | B4: DELA CRUZ | C4: SHAINA | D4: DIMAYUGO | E4: 44796 | F4: =Table1[[#This Row],[DATE HIRED]]+184 -> 44980 | G4: REGULAR
A5: 0015 | B5: JOSAFAT | C5: RENALYN | D5: ABAMO | E5: 44798 | F5: =Table1[[#This Row],[DATE HIRED]]+184 -> 44982 | G5: REGULAR
A6: 0013 | B6: GALGO | C6: CEDRICK | D6: CRUZ | E6: 44805 | F6: =Table1[[#This Row],[DATE HIRED]]+181 -> 44986 | G6: REGULAR
A7: 0018 | B7: OTSUKA | C7: SHIGERU | D7: CENTINA | E7: 44805 | F7: =Table1[[#This Row],[DATE HIRED]]+181 -> 44986 | G7: REGULAR
A8: 0007 | B8: ALIMURONG | C8: JOEL | D8: LUSUNG | E8: 44810 | F8: =Table1[[#This Row],[DATE HIRED]]+181 -> 44991 | G8: REGULAR
A9: 0012 | B9: FERNANDEZ | C9: FRANCIS EMMANUEL | D9: VELOSO | E9: 44823 | F9: =Table1[[#This Row],[DATE HIRED]]+181 -> 45004 | G9: REGULAR
A10: 0009 | B10: CASTRO | C10: AIZEL | D10: SANTOS | E10: 44830 | F10: =Table1[[#This Row],[DATE HIRED]]+181 -> 45011 | G10: REGULAR
A11: 0010 | B11: COLIS | C11: REYMARK BRYAN | D11: SILVANO | E11: 44830 | F11: =Table1[[#This Row],[DATE HIRED]]+181 -> 45011 | G11: REGULAR
A12: 0004 | B12: SARTHOU | C12: IAN MICHAEL LOUIE | D12: ALEGA | E12: 44963 | F12: =Table1[[#This Row],[DATE HIRED]]+150 -> 45113 | G12: REGULAR
A13: 0019 | B13: RONQUILLO | C13: RHEGENE | D13: INGAT | E13: 45028 | F13: =Table1[[#This Row],[DATE HIRED]]+180 -> 45208 | G13: REGULAR
A14: 0020 | B14: SORIANO | C14: MARY ANN | D14: VALLEJOS | E14: 45028 | F14: =Table1[[#This Row],[DATE HIRED]]+180 -> 45208 | G14: REGULAR
A15: 0014 | B15: GATBONTON | C15: BEVERLY | D15: TALOBAN | E15: 45030 | F15: =Table1[[#This Row],[DATE HIRED]]+180 -> 45210 | G15: REGULAR
A16: 0016 | B16: MALINAO | C16: ROGELIO | D16: DELA PENA | E16: 45040 | F16: =Table1[[#This Row],[DATE HIRED]]+180 -> 45220 | G16: REGULAR
A17: 0005 | B17: AGAS | C17: JILLIAN | D17: LAO | E17: 45048 | F17: =Table1[[#This Row],[DATE HIRED]]+180 -> 45228 | G17: REGULAR
A18: 0017 | B18: NAVALON | C18: EVANEL | D18: CAACBAY | E18: 45048 | F18: =Table1[[#This Row],[DATE HIRED]]+180 -> 45228 | G18: REGULAR
A19: 0006 | B19: AGUILAR | C19: IAN MYCO | E19: 45056 | F19: =Table1[[#This Row],[DATE HIRED]]+180 -> 45236 | G19: REGULAR
A20: 0021 | B20: MATAGA | C20: EDITH | D20: DAVID | E20: 45110 | F20: =Table1[[#This Row],[DATE HIRED]]+180 -> 45290 | G20: PROBATIONARY
A21: 0022 | B21: BENALLA | C21: RENNECA | D21: Villapaña | E21: 45110 | F21: =Table1[[#This Row],[DATE HIRED]]+180 -> 45290 | G21: PROBATIONARY
A22: 0023 | B22: OCAMPO | C22: ALFRED | D22: Naguit | E22: 45110 | F22: =Table1[[#This Row],[DATE HIRED]]+180 -> 45290 | G22: PROBATIONARY
A23: 0024 | B23: CARO | C23: ROEL | D23: MALONZO | E23: 45110 | F23: =Table1[[#This Row],[DATE HIRED]]+180 -> 45290 | G23: PROBATIONARY
A24: 0025 | B24: EMBUSCADO | C24: EVER | D24: A | E24: 45139 | F24: =Table1[[#This Row],[DATE HIRED]]+180 -> 45319 | G24: PROBATIONARY
A25: 0026 | B25: TRINIDAD | C25: JENNIFER | D25: M | E25: 45145 | F25: =Table1[[#This Row],[DATE HIRED]]+180 -> 45325 | G25: PROBATIONARY
A26: 0027 | B26: MENDOZA | C26: SEAN JUSTINE | D26: F | E26: 45154 | F26: =Table1[[#This Row],[DATE HIRED]]+180 -> 45334 | G26: PROBATIONARY
A27: 0028 | B27: GATBONTON | C27: ANALIZA | D27: TALOBAN | E27: 45159 | F27: =Table1[[#This Row],[DATE HIRED]]+180 -> 45339 | G27: PROBATIONARY
A28: 0029 | B28: BASILIO | C28: ABIGAIL ANN | D28: Q | E28: 45159 | F28: =Table1[[#This Row],[DATE HIRED]]+180 -> 45339 | G28: PROBATIONARY
A29: 0030 | B29: CRISANTO | C29: ELRITZ | D29: T | E29: 45159 | F29: =Table1[[#This Row],[DATE HIRED]]+180 -> 45339 | G29: PROBATIONARY
A30: 0031 | B30: PABILLANO | C30: FRANKLIN ROOS | D30: C | E30: 45233 | F30: =Table1[[#This Row],[DATE HIRED]]+180 -> 45413 | G30: PROBATIONARY
F31: =Table1[[#This Row],[DATE HIRED]]+160 -> 160

Sheet 2023 ACCRUAL
A1: NAME | D1: Leave Credits from OCC YR 2022 | E1: YR 2023 TOTAL | F1: JAN.2023 | H1: FEB.2023 | J1: MAR.2023 | L1: APR.2023 | N1: MAY.2023 | P1: JUN.2023 | R1: JUL.2023 | T1: AUG.2023 | V1: SEPT.2023 | X1: OCT.2023 | Z1: NOV.2023 | AB1: DEC.2023 | AD1: REMAINING LEAVE (2023)
F2: Consumed | G2: Remaining | H2: Consumed | I2: Remaining | J2: Consumed | K2: Remaining | L2: Consumed | M2: Remaining | N2: Consumed | O2: Remaining | P2: Consumed | Q2: Remaining | R2: Consumed | S2: Remaining | T2: Consumed | U2: Remaining | V2: Consumed | W2: Remaining | X2: Consumed | Y2: Remaining | Z2: Consumed | AA2: Remaining | AB2: Consumed | AC2: Remaining
A3: ANTONIO, VINCENT KEVIN SANTOS
C4: Vacation Leave | D4: 5 | E4: 15 | G4: =$E4/12-F4+D4 -> 6.25 | I4: =$E4/12+G4-H4 -> 7.5 | J4: 1 | K4: =$E4/12+I4-J4 -> 7.75 | L4: 1 | M4: =$E4/12+K4-L4 -> 8 | O4: =$E4/12+M4-N4 -> 9.25 | Q4: =$E4/12+O4-P4 -> 10.5 | R4: 1 | S4: =$E4/12+Q4-R4 -> 10.75 | U4: =$E4/12+S4-T4 -> 12 | V4: 2 | W4: =$E4/12+U4-V4 -> 11.25 | Y4: =$E4/12+W4-X4 -> 12.5 | AA4: =$E4/12+Y4-Z4 -> 13.75 | AB4: 4 | AC4: =$E4/12+AA4-AB4 -> 11 | AD4: VL | AE4: =AC4 -> 11
C5: Sick Leave | D5: 1.68 | E5: 5 | G5: =$E5/12-F5+D5 -> 2.0966667 | I5: =$E5/12+G5-H5 -> 2.5133333 | K5: =$E5/12+I5-J5 -> 2.93 | M5: =$E5/12+K5-L5 -> 3.3466667 | O5: =$E5/12+M5-N5 -> 3.7633333 | P5: 1 | Q5: =$E5/12+O5-P5 -> 3.18 | S5: =$E5/12+Q5-R5 -> 3.5966667 | U5: =$E5/12+S5-T5 -> 4.0133333 | W5: =$E5/12+U5-V5 -> 4.43 | Y5: =$E5/12+W5-X5 -> 4.8466667 | AA5: =$E5/12+Y5-Z5 -> 5.2633333 | AC5: =$E5/12+AA5-AB5 -> 5.68 | AD5: SL | AE5: =AC5 -> 5.68
A6: DELA CRUZ, SHAINA DIMAYUGO
C7: Vacation Leave | D7: 5 | E7: 15 | G7: =$E7/12-F7+D7 -> 6.25 | I7: =$E7/12+G7-H7 -> 7.5 | J7: 1 | K7: =$E7/12+I7-J7 -> 7.75 | M7: =$E7/12+K7-L7 -> 9 | O7: =$E7/12+M7-N7 -> 10.25 | P7: 2 | Q7: =$E7/12+O7-P7 -> 9.5 | R7: 1 | S7: =$E7/12+Q7-R7 -> 9.75 | T7: 3 | U7: =$E7/12+S7-T7 -> 8 | W7: =$E7/12+U7-V7 -> 9.25 | Y7: =$E7/12+W7-X7 -> 10.5 | Z7: 2 | AA7: =$E7/12+Y7-Z7 -> 9.75 | AB7: 8 | AC7: =$E7/12+AA7-AB7 -> 3 | AD7: VL | AE7: =AC7 -> 3
C8: Sick Leave | D8: 0.42 | E8: 5 | G8: =$E8/12-F8+D8 -> 0.83666667 | I8: =$E8/12+G8-H8 -> 1.2533333 | J8: 1 | K8: =$E8/12+I8-J8 -> 0.67 | M8: =$E8/12+K8-L8 -> 1.0866667 | O8: =$E8/12+M8-N8 -> 1.5033333 | Q8: =$E8/12+O8-P8 -> 1.92 | S8: =$E8/12+Q8-R8 -> 2.3366667 | U8: =$E8/12+S8-T8 -> 2.7533333 | V8: 1 | W8: =$E8/12+U8-V8 -> 2.17 | Y8: =$E8/12+W8-X8 -> 2.5866667 | AA8: =$E8/12+Y8-Z8 -> 3.0033333 | AC8: =$E8/12+AA8-AB8 -> 3.42 | AD8: SL | AE8: =AC8 -> 3.42
A9: JOSAFAT, RENALYN
C10: Vacation Leave | D10: 5 | E10: 15 | G10: =$E10/12-F10+D10 -> 6.25 | I10: =$E10/12+G10-H10 -> 7.5 | J10: 1 | K10: =$E10/12+I10-J10 -> 7.75 | M10: =$E10/12+K10-L10 -> 9 | O10: =$E10/12+M10-N10 -> 10.25 | P10: 2 | Q10: =$E10/12+O10-P10 -> 9.5 | S10: =$E10/12+Q10-R10 -> 10.75 | U10: =$E10/12+S10-T10 -> 12 | W10: =$E10/12+U10-V10 -> 13.25 | Y10: =$E10/12+W10-X10 -> 14.5 | AA10: =$E10/12+Y10-Z10 -> 15.75 | AB10: 10 | AC10: =$E10/12+AA10-AB10 -> 7 | AD10: VL | AE10: =AC10 -> 7
C11: Sick Leave | D11: 1.68 | E11: 5 | G11: =$E11/12-F11+D11 -> 2.0966667 | I11: =$E11/12+G11-H11 -> 2.5133333 | J11: 1 | K11: =$E11/12+I11-J11 -> 1.93 | L11: 1 | M11: =$E11/12+K11-L11 -> 1.3466667 | N11: 1 | O11: =$E11/12+M11-N11 -> 0.76333333 | Q11: =$E11/12+O11-P11 -> 1.18 | R11: 1 | S11: =$E11/12+Q11-R11 -> 0.59666667 | T11: 1 | U11: =$E11/12+S11-T11 -> 0.013333333 | V11: 2 | W11: =$E11/12+U11-V11 -> -1.57 | Y11: =$E11/12+W11-X11 -> -1.1533333 | AA11: =$E11/12+Y11-Z11 -> -0.73666667 | AC11: =$E11/12+AA11-AB11 -> -0.32 | AD11: SL | AE11: =AC11 -> -0.32
A12: GALGO, CEDRICK CRUZ
C13: Vacation Leave | D13: 5 | E13: 15 | G13: =$E13/12-F13+D13 -> 6.25 | I13: =$E13/12+G13-H13 -> 7.5 | K13: =$E13/12+I13-J13 -> 8.75 | L13: 2 | M13: =$E13/12+K13-L13 -> 8 | O13: =$E13/12+M13-N13 -> 9.25 | P13: 0.5 | Q13: =$E13/12+O13-P13 -> 10 | R13: 1 | S13: =$E13/12+Q13-R13 -> 10.25 | U13: =$E13/12+S13-T13 -> 11.5 | W13: =$E13/12+U13-V13 -> 12.75 | Y13: =$E13/12+W13-X13 -> 14 | Z13: 1 | AA13: =$E13/12+Y13-Z13 -> 14.25 | AB13: 3 | AC13: =$E13/12+AA13-AB13 -> 12.5 | AD13: VL | AE13: =AC13 -> 12.5
C14: Sick Leave | D14: 1.68 | E14: 5 | G14: =$E14/12-F14+D14 -> 2.0966667 | I14: =$E14/12+G14-H14 -> 2.5133333 | K14: =$E14/12+I14-J14 -> 2.93 | M14: =$E14/12+K14-L14 -> 3.3466667 | O14: =$E14/12+M14-N14 -> 3.7633333 | Q14: =$E14/12+O14-P14 -> 4.18 | S14: =$E14/12+Q14-R14 -> 4.5966667 | U14: =$E14/12+S14-T14 -> 5.0133333 | V14: 2 | W14: =$E14/12+U14-V14 -> 3.43 | Y14: =$E14/12+W14-X14 -> 3.8466667 | AA14: =$E14/12+Y14-Z14 -> 4.2633333 | AC14: =$E14/12+AA14-AB14 -> 4.68 | AD14: SL | AE14: =AC14 -> 4.68
A15: OTSUKA, SHIGERU CENTINA
C16: Vacation Leave | D16: 5 | E16: 15 | G16: =$E16/12-F16+D16 -> 6.25 | I16: =$E16/12+G16-H16 -> 7.5 | K16: =$E16/12+I16-J16 -> 8.75 | M16: =$E16/12+K16-L16 -> 10 | N16: 0.5 | O16: =$E16/12+M16-N16 -> 10.75 | Q16: =$E16/12+O16-P16 -> 12 | S16: =$E16/12+Q16-R16 -> 13.25 | U16: =$E16/12+S16-T16 -> 14.5 | V16: 2 | W16: =$E16/12+U16-V16 -> 13.75 | X16: 2 | Y16: =$E16/12+W16-X16 -> 13 | AA16: =$E16/12+Y16-Z16 -> 14.25 | AB16: 8 | AC16: =$E16/12+AA16-AB16 -> 7.5 | AD16: VL | AE16: =AC16 -> 7.5
C17: Sick Leave | D17: 1.68 | E17: 5 | G17: =$E17/12-F17+D17 -> 2.0966667 | I17: =$E17/12+G17-H17 -> 2.5133333 | J17: 1 | K17: =$E17/12+I17-J17 -> 1.93 | L17: 1 | M17: =$E17/12+K17-L17 -> 1.3466667 | O17: =$E17/12+M17-N17 -> 1.7633333 | Q17: =$E17/12+O17-P17 -> 2.18 | S17: =$E17/12+Q17-R17 -> 2.5966667 | T17: 1 | U17: =$E17/12+S17-T17 -> 2.0133333 | V17: 1 | W17: =$E17/12+U17-V17 -> 1.43 | Y17: =$E17/12+W17-X17 -> 1.8466667 | AA17: =$E17/12+Y17-Z17 -> 2.2633333 | AC17: =$E17/12+AA17-AB17 -> 2.68 | AD17: SL | AE17: =AC17 -> 2.68
A18: ALIMURONG, JOEL LUSUNG
C19: Vacation Leave | D19: 3.75 | E19: 15 | G19: =$E19/12-F19+D19 -> 5 | I19: =$E19/12+G19-H19 -> 6.25 | K19: =$E19/12+I19-J19 -> 7.5 | M19: =$E19/12+K19-L19 -> 8.75 | O19: =$E19/12+M19-N19 -> 10 | Q19: =$E19/12+O19-P19 -> 11.25 | S19: =$E19/12+Q19-R19 -> 12.5 | U19: =$E19/12+S19-T19 -> 13.75 | W19: =$E19/12+U19-V19 -> 15 | Y19: =$E19/12+W19-X19 -> 16.25 | AA19: =$E19/12+Y19-Z19 -> 17.5 | AB19: 8 | AC19: =$E19/12+AA19-AB19 -> 10.75 | AD19: VL | AE19: =AC19 -> 10.75
C20: Sick Leave | D20: 1.26 | E20: 5 | G20: =$E20/12-F20+D20 -> 1.6766667 | I20: =$E20/12+G20-H20 -> 2.0933333 | K20: =$E20/12+I20-J20 -> 2.51 | M20: =$E20/12+K20-L20 -> 2.9266667 | O20: =$E20/12+M20-N20 -> 3.3433333 | Q20: =$E20/12+O20-P20 -> 3.76 | S20: =$E20/12+Q20-R20 -> 4.1766667 | U20: =$E20/12+S20-T20 -> 4.5933333 | W20: =$E20/12+U20-V20 -> 5.01 | Y20: =$E20/12+W20-X20 -> 5.4266667 | AA20: =$E20/12+Y20-Z20 -> 5.8433333 | AC20: =$E20/12+AA20-AB20 -> 6.26 | AD20: SL | AE20: =AC20 -> 6.26
A21: FERNANDEZ, FRANCIS EMMANUEL VELOSO
C22: Vacation Leave | D22: 3.75 | E22: 15 | G22: =$E22/12-F22+D22 -> 5 | I22: =$E22/12+G22-H22 -> 6.25 | K22: =$E22/12+I22-J22 -> 7.5 | L22: 1 | M22: =$E22/12+K22-L22 -> 7.75 | N22: 5 | O22: =$E22/12+M22-N22 -> 4 | Q22: =$E22/12+O22-P22 -> 5.25 | S22: =$E22/12+Q22-R22 -> 6.5 | U22: =$E22/12+S22-T22 -> 7.75 | V22: 0.5 | W22: =$E22/12+U22-V22 -> 8.5 | Y22: =$E22/12+W22-X22 -> 9.75 | AA22: =$E22/12+Y22-Z22 -> 11 | AB22: 3 | AC22: =$E22/12+AA22-AB22 -> 9.25 | AD22: VL | AE22: =AC22 -> 9.25
C23: Sick Leave | D23: 1.26 | E23: 5 | G23: =$E23/12-F23+D23 -> 1.6766667 | I23: =$E23/12+G23-H23 -> 2.0933333 | J23: 1 | K23: =$E23/12+I23-J23 -> 1.51 | M23: =$E23/12+K23-L23 -> 1.9266667 | N23: 1 | O23: =$E23/12+M23-N23 -> 1.3433333 | Q23: =$E23/12+O23-P23 -> 1.76 | S23: =$E23/12+Q23-R23 -> 2.1766667 | U23: =$E23/12+S23-T23 -> 2.5933333 | W23: =$E23/12+U23-V23 -> 3.01 | X23: 3 | Y23: =$E23/12+W23-X23 -> 0.42666667 | AA23: =$E23/12+Y23-Z23 -> 0.84333333 | AC23: =$E23/12+AA23-AB23 -> 1.26 | AD23: SL | AE23: =AC23 -> 1.26
A24: CASTRO, AIZEL SANTOS
C25: Vacation Leave | D25: 3.75 | E25: 15 | G25: =$E25/12-F25+D25 -> 5 | I25: =$E25/12+G25-H25 -> 6.25 | J25: 1.5 | K25: =$E25/12+I25-J25 -> 6 | L25: 1 | M25: =$E25/12+K25-L25 -> 6.25 | O25: =$E25/12+M25-N25 -> 7.5 | Q25: =$E25/12+O25-P25 -> 8.75 | S25: =$E25/12+Q25-R25 -> 10 | U25: =$E25/12+S25-T25 -> 11.25 | W25: =$E25/12+U25-V25 -> 12.5 | Y25: =$E25/12+W25-X25 -> 13.75 | AA25: =$E25/12+Y25-Z25 -> 15 | AB25: 3 | AC25: =$E25/12+AA25-AB25 -> 13.25 | AD25: VL | AE25: =AC25 -> 13.25
C26: Sick Leave | D26: 1.26 | E26: 5 | G26: =$E26/12-F26+D26 -> 1.6766667 | I26: =$E26/12+G26-H26 -> 2.0933333 | K26: =$E26/12+I26-J26 -> 2.51 | M26: =$E26/12+K26-L26 -> 2.9266667 | O26: =$E26/12+M26-N26 -> 3.3433333 | Q26: =$E26/12+O26-P26 -> 3.76 | S26: =$E26/12+Q26-R26 -> 4.1766667 | T26: 1 | U26: =$E26/12+S26-T26 -> 3.5933333 | W26: =$E26/12+U26-V26 -> 4.01 | X26: 2 | Y26: =$E26/12+W26-X26 -> 2.4266667 | Z26: 4 | AA26: =$E26/12+Y26-Z26 -> -1.1566667 | AC26: =$E26/12+AA26-AB26 -> -0.74 | AD26: SL | AE26: =AC26 -> -0.74
A27: COLIS, REYMARK BRYAN SILVANO
C28: Vacation Leave | D28: 3.75 | E28: 15 | G28: =$E28/12-F28+D28 -> 5 | I28: =$E28/12+G28-H28 -> 6.25 | K28: =$E28/12+I28-J28 -> 7.5 | M28: =$E28/12+K28-L28 -> 8.75 | N28: 3 | O28: =$E28/12+M28-N28 -> 7 | Q28: =$E28/12+O28-P28 -> 8.25 | S28: =$E28/12+Q28-R28 -> 9.5 | U28: =$E28/12+S28-T28 -> 10.75 | V28: 2 | W28: =$E28/12+U28-V28 -> 10 | Y28: =$E28/12+W28-X28 -> 11.25 | Z28: 1 | AA28: =$E28/12+Y28-Z28 -> 11.5 | AB28: 6 | AC28: =$E28/12+AA28-AB28 -> 6.75 | AD28: VL | AE28: =AC28 -> 6.75
C29: Sick Leave | D29: 1.26 | E29: 5 | G29: =$E29/12-F29+D29 -> 1.6766667 | I29: =$E29/12+G29-H29 -> 2.0933333 | K29: =$E29/12+I29-J29 -> 2.51 | M29: =$E29/12+K29-L29 -> 2.9266667 | O29: =$E29/12+M29-N29 -> 3.3433333 | Q29: =$E29/12+O29-P29 -> 3.76 | S29: =$E29/12+Q29-R29 -> 4.1766667 | U29: =$E29/12+S29-T29 -> 4.5933333 | W29: =$E29/12+U29-V29 -> 5.01 | Y29: =$E29/12+W29-X29 -> 5.4266667 | AA29: =$E29/12+Y29-Z29 -> 5.8433333 | AC29: =$E29/12+AA29-AB29 -> 6.26 | AD29: SL | AE29: =AC29 -> 6.26
A30: SARTHOU, IAN MICHAEL LOUIE ALEGA
C31: Vacation Leave | E31: 15 | I31: =$E31/12+G31-H31 -> 1.25 | K31: =$E31/12+I31-J31 -> 2.5 | M31: =$E31/12+K31-L31 -> 3.75 | O31: =$E31/12+M31-N31 -> 5 | Q31: =$E31/12+O31-P31 -> 6.25 | S31: =$E31/12+Q31-R31 -> 7.5 | U31: =$E31/12+S31-T31 -> 8.75 | W31: =$E31/12+U31-V31 -> 10 | Y31: =$E31/12+W31-X31 -> 11.25 | AA31: =$E31/12+Y31-Z31 -> 12.5 | AB31: 7 | AC31: =$E31/12+AA31-AB31 -> 6.75 | AD31: VL | AE31: =AC31 -> 6.75
C32: Sick Leave | E32: 5 | I32: =$E32/12+G32-H32 -> 0.41666667 | K32: =$E32/12+I32-J32 -> 0.83333333 | M32: =$E32/12+K32-L32 -> 1.25 | O32: =$E32/12+M32-N32 -> 1.6666667 | Q32: =$E32/12+O32-P32 -> 2.0833333 | S32: =$E32/12+Q32-R32 -> 2.5 | U32: =$E32/12+S32-T32 -> 2.9166667 | W32: =$E32/12+U32-V32 -> 3.3333333 | Y32: =$E32/12+W32-X32 -> 3.75 | AA32: =$E32/12+Y32-Z32 -> 4.1666667 | AC32: =$E32/12+AA32-AB32 -> 4.5833333 | AD32: SL | AE32: =AC32 -> 4.5833333
A33: RONQUILLO, RHEGENE INGAT
C34: Vacation Leave | E34: 15 | M34: =$E34/12+K34-L34 -> 1.25 | O34: =$E34/12+M34-N34 -> 2.5 | Q34: =$E34/12+O34-P34 -> 3.75 | S34: =$E34/12+Q34-R34 -> 5 | U34: =$E34/12+S34-T34 -> 6.25 | W34: =$E34/12+U34-V34 -> 7.5 | Y34: =$E34/12+W34-X34 -> 8.75 | Z34: 1 | AA34: =$E34/12+Y34-Z34 -> 9 | AB34: 3 | AC34: =$E34/12+AA34-AB34 -> 7.25 | AD34: VL | AE34: =AC34 -> 7.25
C35: Sick Leave | E35: 5 | M35: =$E35/12+K35-L35 -> 0.41666667 | O35: =$E35/12+M35-N35 -> 0.83333333 | Q35: =$E35/12+O35-P35 -> 1.25 | S35: =$E35/12+Q35-R35 -> 1.6666667 | U35: =$E35/12+S35-T35 -> 2.0833333 | W35: =$E35/12+U35-V35 -> 2.5 | X35: 1 | Y35: =$E35/12+W35-X35 -> 1.9166667 | AA35: =$E35/12+Y35-Z35 -> 2.3333333 | AC35: =$E35/12+AA35-AB35 -> 2.75 | AD35: SL | AE35: =AC35 -> 2.75
A36: SORIANO, MARY ANN VALLEJOS
C37: Vacation Leave | E37: 15 | M37: =$E37/12+K37-L37 -> 1.25 | O37: =$E37/12+M37-N37 -> 2.5 | Q37: =$E37/12+O37-P37 -> 3.75 | S37: =$E37/12+Q37-R37 -> 5 | U37: =$E37/12+S37-T37 -> 6.25 | W37: =$E37/12+U37-V37 -> 7.5 | Y37: =$E37/12+W37-X37 -> 8.75 | Z37: 2 | AA37: =$E37/12+Y37-Z37 -> 8 | AB37: 5 | AC37: =$E37/12+AA37-AB37 -> 4.25 | AD37: VL | AE37: =AC37 -> 4.25
C38: Sick Leave | E38: 5 | M38: =$E38/12+K38-L38 -> 0.41666667 | O38: =$E38/12+M38-N38 -> 0.83333333 | Q38: =$E38/12+O38-P38 -> 1.25 | S38: =$E38/12+Q38-R38 -> 1.6666667 | U38: =$E38/12+S38-T38 -> 2.0833333 | W38: =$E38/12+U38-V38 -> 2.5 | Y38: =$E38/12+W38-X38 -> 2.9166667 | AA38: =$E38/12+Y38-Z38 -> 3.3333333 | AC38: =$E38/12+AA38-AB38 -> 3.75 | AD38: SL | AE38: =AC38 -> 3.75
A39: GATBONTON, BEVERLY TALOBAN
C40: Vacation Leave | E40: 15 | L40: 0.5 | M40: =$E40/12+K40-L40 -> 0.75 | O40: =$E40/12+M40-N40 -> 2 | Q40: =$E40/12+O40-P40 -> 3.25 | S40: =$E40/12+Q40-R40 -> 4.5 | U40: =$E40/12+S40-T40 -> 5.75 | W40: =$E40/12+U40-V40 -> 7 | Y40: =$E40/12+W40-X40 -> 8.25 | AA40: =$E40/12+Y40-Z40 -> 9.5 | AB40: 5 | AC40: =$E40/12+AA40-AB40 -> 5.75 | AD40: VL | AE40: =AC40 -> 5.75
...

Sheet DEC
A1: NAME | B1: VL | C1: SL | D1: SPL | E1: 45627 | F1: 45628 | G1: 45629 | H1: 45630 | I1: 45631 | J1: 45632 | K1: 45633 | L1: 45634 | M1: 45635 | N1: 45636 | O1: 45637 | P1: 45638 | Q1: 45639 | R1: 45640 | S1: 45641 | T1: 45642 | U1: 45643 | V1: 45644 | W1: 45645 | X1: 45646 | Y1: 45647 | Z1: 45648 | AA1: 45649 | AB1: 45650 | AC1: 45651 | AD1: 45652 | AE1: 45653 | AF1: 45654 | AG1: 45655 | AH1: 45656 | AI1: 45657
A2: AGAS, JILLIAN LAO | B2: =NOV!B2 + 1.25 - (COUNTIF(E2:AI2, "VL") * 1) - (COUNTIF(E2:AH2, "HDL") * 0.5) -> 7 | C2: =NOV!C2+ 0.416666666666666 - COUNTIF(E2:AH2, "SL")-(COUNTIF(E2:AH2, "HDSL") * 0.5) -> 0.33333333 | N2: SL | AB2: VL | AE2: VL | AF2: VL | AI2: VL
A3: AGUILAR, IAN MYCO | B3: =NOV!B3 + 1.25 - (COUNTIF(E3:AH3, "VL") * 1) - (COUNTIF(E3:AH3, "HDL") * 0.5) -> 14 | C3: =NOV!C3+ 0.416666666666666 - COUNTIF(E3:AH3, "SL")-(COUNTIF(E3:AH3, "HDSL") * 0.5) -> 0.33333333 | F3: SL | X3: VL | AA3: VL | AB3: VL | AE3: VL | AI3: VL
A4: ALIMURONG, JOEL LUSUNG | B4: =NOV!B4 + 1.25 - (COUNTIF(E4:AH4, "VL") * 1) - (COUNTIF(E4:AH4, "HDL") * 0.5) -> 19.75 | C4: =NOV!C4+ 0.416666666666666 - COUNTIF(E4:AH4, "SL")-(COUNTIF(E4:AH4, "HDSL") * 0.5) -> 0.26 | F4: SL | I4: SL | J4: SL | O4: SL | T4: SL | U4: SL | X4: SL | AA4: SL | AB4: VL | AE4: VL | AI4: VL
A5: ANTONIO, VINCENT KEVIN SANTOS | B5: =NOV!B5 + 1.25 - (COUNTIF(E5:AH5, "VL") * 1) - (COUNTIF(E5:AH5, "HDL") * 0.5) -> 9.5 | C5: =NOV!C5+ 0.416666666666666 - COUNTIF(E5:AH5, "SL")-(COUNTIF(E5:AH5, "HDSL") * 0.5) -> 0.18 | J5: SL | U5: SL | V5: SL | X5: HDSL | AA5: SL | AB5: VL | AE5: SL | AI5: SL
A6: AUSTRIA, LOUIS FERNAND BALUYOT | B6: =NOV!B6 + 1.25 - (COUNTIF(E6:AH6, "VL") * 1) - (COUNTIF(E6:AH6, "HDL") * 0.5) -> 2 | C6: =NOV!C6+ 0.416666666666666 - COUNTIF(E6:AH6, "SL")-(COUNTIF(E6:AH6, "HDSL") * 0.5) -> 3.3333333 | T6: VL | U6: VL | V6: VL | W6: VL | X6: VL | AA6: VL | AB6: VL | AE6: VL | AI6: VL
A7: BACONGALLO, NIKA NUEVA | B7: =NOV!B7 + 1.25 - (COUNTIF(E7:AH7, "VL") * 1) - (COUNTIF(E7:AH7, "HDL") * 0.5) -> 3.75 | C7: =NOV!C7+ 0.416666666666666 - COUNTIF(E7:AH7, "SL")-(COUNTIF(E7:AH7, "HDSL") * 0.5) -> 0.91666667 | J7: SL | W7: VL | X7: VL | AA7: VL | AB7: VL | AE7: VL | AI7: VL
A8: BANSIL, KRISTIAN DAVID | B8: =NOV!B8 + 1.25 - (COUNTIF(E8:AH8, "VL") * 1) - (COUNTIF(E8:AH8, "HDL") * 0.5) -> 6.5 | C8: =NOV!C8+ 0.416666666666666 - COUNTIF(E8:AH8, "SL")-(COUNTIF(E8:AH8, "HDSL") * 0.5) -> 4.1666667 | T8: VL | U8: VL | V8: VL | W8: VL | AA8: VL | AB8: VL | AI8: VL
A9: BENALLA, RENNECA Villapaña | B9: =NOV!B9 + 1.25 - (COUNTIF(E9:AH9, "VL") * 1) - (COUNTIF(E9:AH9, "HDL") * 0.5) -> 11.25 | C9: =NOV!C9+ 0.416666666666666 - COUNTIF(E9:AH9, "SL")-(COUNTIF(E9:AH9, "HDSL") * 0.5) -> 4.0833333 | AB9: VL | AI9: VL
A10: CAMERINO, YRIS GAELLE PARREÑAS | B10: =NOV!B10 + 1.25 - (COUNTIF(E10:AH10, "VL") * 1) - (COUNTIF(E10:AH10, "HDL") * 0.5) -> 6 | C10: =NOV!C10+ 0.416666666666666 - COUNTIF(E10:AH10, "SL")-(COUNTIF(E10:AH10, "HDSL") * 0.5) -> 0.33333333 | I10: SL | J10: SL | Q10: VL | X10: VL | AA10: VL | AE10: VL
A11: CASTRO, AIZEL SANTOS | B11: =NOV!B11 + 1.25 - (COUNTIF(E11:AH11, "VL") * 1) - (COUNTIF(E11:AH11, "HDL") * 0.5) -> 11.25 | C11: =NOV!C11+ 0.416666666666666 - COUNTIF(E11:AH11, "SL")-(COUNTIF(E11:AH11, "HDSL") * 0.5) -> 0.26 | D11: =NOV!D11- COUNTIF(E11:AH11, "SPL") -> 5.1666667 | G11: SPL | AA11: VL | AB11: VL | AE11: VL | AI11: VL
A12: CASTILLANO, DENVER ORLANDA | B12: =NOV!B12 + 1.25 - (COUNTIF(E12:AH12, "VL") * 1) - (COUNTIF(E12:AH12, "HDL") * 0.5) -> 4.5 | C12: =NOV!C12+ 0.416666666666666 - COUNTIF(E12:AH12, "SL")-(COUNTIF(E12:AH12, "HDSL") * 0.5) -> 1.5 | F12: SL | W12: VL | AA12: VL | AB12: VL | AI12: VL
A13: CATOLOGO, MARNIE | B13: =1.25*6- (COUNTIF(E13:AH13, "VL") * 1) - (COUNTIF(E13:AH13, "HDL") * 0.5) -> 6.5 | C13: =0.416666666666666*6 - COUNTIF(E13:AH13, "SL")-(COUNTIF(E13:AH13, "HDSL") * 0.5) -> 2.5 | P13: VL
A14: COLIS, REYMARK BRYAN SILVANO | B14: =NOV!B13 + 1.25 - (COUNTIF(E14:AH14, "VL") * 1) - (COUNTIF(E14:AH14, "HDL") * 0.5) -> 7.625 | C14: =NOV!C13+ 0.416666666666666 - COUNTIF(E14:AH14, "SL")-(COUNTIF(E14:AH14, "HDSL") * 0.5) -> 8.26 | AB14: SL
A15: CRISANTO, ELRITZ T | B15: =NOV!B14 + 1.25 - (COUNTIF(E15:AH15, "VL") * 1) - (COUNTIF(E15:AH15, "HDL") * 0.5) -> 10 | C15: =NOV!C14+ 0.416666666666666 - COUNTIF(E15:AH15, "SL")-(COUNTIF(E15:AH15, "HDSL") * 0.5) -> 0.16666667 | G15: SL | J15: HDSL | P15: VL | Q15: VL | T15: VL | AA15: VL | AB15: VL | AE15: VL | AI15: VL
A16: DELA CRUZ, SHAINA DIMAYUGO | B16: =NOV!B15 + 1.25 - (COUNTIF(E16:AH16, "VL") * 1) - (COUNTIF(E16:AH16, "HDL") * 0.5) -> 0.75 | C16: =NOV!C15+ 0.416666666666666 - COUNTIF(E16:AH16, "SL")-(COUNTIF(E16:AH16, "HDSL") * 0.5) -> 0.25 | Q16: SL | AA16: VL | AB16: VL | AE16: VL
A17: EMBUSCADO, EVER A | B17: =NOV!B16 + 1.25 - (COUNTIF(E17:AH17, "VL") * 1) - (COUNTIF(E17:AH17, "HDL") * 0.5) -> 11.25 | C17: =NOV!C16+ 0.416666666666666 - COUNTIF(E17:AH17, "SL")-(COUNTIF(E17:AH17, "HDSL") * 0.5) -> 6.0833333 | T17: VL | U17: VL | V17: VL | W17: VL | X17: VL | AA17: VL | AB17: VL | AE17: VL | AI17: VL
A18: FERNANDEZ, FRANCIS EMMANUEL VELOSO | B18: =NOV!B17 + 1.25 - (COUNTIF(E18:AH18, "VL") * 1) - (COUNTIF(E18:AH18, "HDL") * 0.5) -> 15.25 | C18: =NOV!C17+ 0.416666666666666 - COUNTIF(E18:AH18, "SL")-(COUNTIF(E18:AH18, "HDSL") * 0.5) -> 0.26 | AA18: SL | AE18: SL | AI18: VL
A19: GALGO, CEDRICK CRUZ | B19: =NOV!B18 + 1.25 - (COUNTIF(E19:AH19, "VL") * 1) - (COUNTIF(E19:AH19, "HDL") * 0.5) -> 19.5 | C19: =NOV!C18+ 0.416666666666666 - COUNTIF(E19:AH19, "SL")-(COUNTIF(E19:AH19, "HDSL") * 0.5) -> 4.68 | J19: SL | N19: SL | P19: VL | V19: SL | W19: SL | X19: SL | AA19: VL | AB19: VL | AE19: VL | AI19: VL
A20: GATBONTON, ANALIZA TALOBAN | B20: =NOV!B19 + 1.25 - (COUNTIF(E20:AH20, "VL") * 1) - (COUNTIF(E20:AH20, "HDL") * 0.5) -> 10 | C20: =NOV!C19+ 0.416666666666666 - COUNTIF(E20:AH20, "SL")-(COUNTIF(E20:AH20, "HDSL") * 0.5) -> 0.16666667 | F20: SL | I20: SL | T20: VL | V20: HDSL | X20: VL | AA20: VL | AB20: VL | AE20: VL
A21: GATBONTON, BEVERLY TALOBAN | B21: =NOV!B20 + 1.25 - (COUNTIF(E21:AH21, "VL") * 1) - (COUNTIF(E21:AH21, "HDL") * 0.5) -> 0.25 | C21: =NOV!C20+ 0.416666666666666 - COUNTIF(E21:AH21, "SL")-(COUNTIF(E21:AH21, "HDSL") * 0.5) -> -0.25 | F21: HDL | G21: SL | H21: VL | I21: VL | J21: HDL | AA21: VL
A22: GUECO, JOHANA ROSE PEREZ | B22: =NOV!B21 + 1.25 - (COUNTIF(E22:AH22, "VL") * 1) - (COUNTIF(E22:AH22, "HDL") * 0.5) -> 5 | C22: =NOV!C21+ 0.416666666666666 - COUNTIF(E22:AH22, "SL")-(COUNTIF(E22:AH22, "HDSL") * 0.5) -> 1.3333333 | D22: =NOV!D21- COUNTIF(E22:AH22, "SPL") -> 0 | I22: SPL | J22: SL | P22: SPL | V22: SL | X22: SPL | AA22: VL | AB22: VL | AE22: VL | AI22: SL
A23: JOSAFAT, RENALYN | B23: =NOV!B22 + 1.25 - (COUNTIF(E23:AH23, "VL") * 1) - (COUNTIF(E23:AH23, "HDL") * 0.5) -> 7 | C23: =NOV!C22+ 0.416666666666666 - COUNTIF(E23:AH23, "SL")-(COUNTIF(E23:AH23, "HDSL") * 0.5) -> 0.68 | T23: VL | AA23: VL | AB23: VL | AE23: VL | AI23: VL
A24: LOZANO, ALDWIN JOHN | B24: =NOV!B23 + 1.25 - (COUNTIF(E24:AH24, "VL") * 1) - (COUNTIF(E24:AI24, "HDL") * 0.5) -> 6 | C24: =NOV!C23+ 0.416666666666666 - COUNTIF(E24:AH24, "SL")-(COUNTIF(E24:AH24, "HDSL") * 0.5) -> 1.3333333 | O24: SL | AA24: VL | AB24: VL | AE24: VL | AI24: VL
A25: MALINAO, ROGELIO DELA PENA | B25: =NOV!B24 + 1.25 - (COUNTIF(E25:AH25, "VL") * 1) - (COUNTIF(E25:AH25, "HDL") * 0.5) -> 6.25 | C25: =NOV!C24+ 0.416666666666666 - COUNTIF(E25:AH25, "SL")-(COUNTIF(E25:AH25, "HDSL") * 0.5) -> 0.25 | J25: HDSL | N25: HDSL | Q25: VL | T25: HDSL | AB25: VL | AI25: VL
A26: MATAGA, EDITH DAVID | B26: =NOV!B25 + 1.25 - (COUNTIF(E26:AH26, "VL") * 1) - (COUNTIF(E26:AH26, "HDL") * 0.5) -> 0 | C26: =NOV!C25+ 0.416666666666666 - COUNTIF(E26:AH26, "SL")-(COUNTIF(E26:AH26, "HDSL") * 0.5) -> -2.7200464e-15 | G26: HDL | I26: VL | AF26: HDSL
A27: MENDOZA , SEAN JUSTINE F | B27: =NOV!B26 + 1.25 - (COUNTIF(E27:AH27, "VL") * 1) - (COUNTIF(E27:AH27, "HDL") * 0.5) -> 8.25 | C27: =NOV!C26+ 0.416666666666666 - COUNTIF(E27:AH27, "SL")-(COUNTIF(E27:AH27, "HDSL") * 0.5) -> -0.41666667 | Q27: HDSL | T27: VL | U27: SL | V27: SL | W27: SL | X27: SL | AA27: VL | AB27: VL | AE27: VL | AI27: VL
A28: NAVALON, EVANEL CAACBAY | B28: =NOV!B27 + 1.25 - (COUNTIF(E28:AH28, "VL") * 1) - (COUNTIF(E28:AH28, "HDL") * 0.5) -> 14 | C28: =NOV!C27+ 0.416666666666666 - COUNTIF(E28:AH28, "SL")-(COUNTIF(E28:AH28, "HDSL") * 0.5) -> 0.33333333 | P28: SL | W28: VL | AG28: VL | AI28: VL
A29: OCAMPO, ALFRED NAGUIT | B29: =NOV!B28 + 1.25 - (COUNTIF(E29:AH29, "VL") * 1) - (COUNTIF(E29:AH29, "HDL") * 0.5) -> 8.5 | C29: =NOV!C28+ 0.416666666666666 - COUNTIF(E29:AH29, "SL")-(COUNTIF(E29:AH29, "HDSL") * 0.5) -> 1.5 | T29: SL | U29: SL | X29: SL | AA29: VL | AB29: VL | AE29: VL | AI29: VL
A30: OTSUKA, SHIGERU CENTINA | B30: =NOV!B29 + 1.25 - (COUNTIF(E30:AH30, "VL") * 1) - (COUNTIF(E30:AH30, "HDL") * 0.5) -> 11.5 | C30: =NOV!C29+ 0.416666666666666 - COUNTIF(E30:AH30, "SL")-(COUNTIF(E30:AH30, "HDSL") * 0.5) -> 0.68 | J30: SL | P30: VL
A31: PABILLANO, FRANKLIN ROOS C | B31: =NOV!B30 + 1.25 - (COUNTIF(E31:AH31, "VL") * 1) - (COUNTIF(E31:AI31, "HDL") * 0.5) -> 16.5 | C31: =NOV!C30+ 0.416666666666666 - COUNTIF(E31:AI31, "SL")-(COUNTIF(E31:AH31, "HDSL") * 0.5) -> 2.8333333 | U31: SL | AB31: SL | AI31: SL
A32: PANGAN, CRISTINA MIRANDA | B32: =NOV!B31 + 1.25 - (COUNTIF(E32:AH32, "VL") * 1) - (COUNTIF(E32:AH32, "HDL") * 0.5) -> 6.5 | C32: =NOV!C31+ 0.416666666666666 - COUNTIF(E32:AH32, "SL")-(COUNTIF(E32:AH32, "HDSL") * 0.5) -> 0.33 | J32: HDL | P32: SL | AA32: SL | AB32: SL | AE32: VL
A33: PINEDA, ERIKA SERIOSA | B33: =NOV!B32 + 1.25 - (COUNTIF(E33:AH33, "VL") * 1) - (COUNTIF(E33:AH33, "HDL") * 0.5) -> 3 | C33: =NOV!C32+ 0.416666666666666 - COUNTIF(E33:AH33, "SL")-(COUNTIF(E33:AH33, "HDSL") * 0.5) -> 1.33 | X33: SL | AA33: VL | AB33: VL | AE33: SL | AI33: SL
A34: PATRIMONIO, RYAN REX | B34: =1.25*6- (COUNTIF(E34:AI34, "VL") * 1) - (COUNTIF(E34:AH34, "HDL") * 0.5) -> 5.5 | C34: =0.416666666666666*6 - COUNTIF(E34:AH34, "SL")-(COUNTIF(E34:AH34, "HDSL") * 0.5) -> 0.5 | AA34: SL | AB34: SL | AE34: VL | AI34: VL
A35: RONQUILLO, RHEGENE INGAT | B35: =NOV!B33 + 1.25 - (COUNTIF(E35:AH35, "VL") * 1) - (COUNTIF(E35:AH35, "HDL") * 0.5) -> 8.25 | C35: =NOV!C33+ 0.416666666666666 - COUNTIF(E35:AH35, "SL")-(COUNTIF(E35:AH35, "HDSL") * 0.5) -> 0.75 | G35: VL | O35: SL | P35: SL | AA35: SL | AI35: SL
A36: SAMODIO, JHUNEL CARLO TRAIFALGAR | B36: =NOV!B34 + 1.25 - (COUNTIF(E36:AH36, "VL") * 1) - (COUNTIF(E36:AH36, "HDL") * 0.5) -> 6 | C36: =NOV!C34+ 0.416666666666666 - COUNTIF(E36:AH36, "SL")-(COUNTIF(E36:AH36, "HDSL") * 0.5) -> 0.33333333 | P36: SL | X36: VL | AA36: VL | AB36: VL | AE36: VL | AI36: VL
A37: SARTHOU, IAN MICHAEL LOUIE ALEGA | B37: =NOV!B35 + 1.25 - (COUNTIF(E37:AH37, "VL") * 1) - (COUNTIF(E37:AH37, "HDL") * 0.5) -> 20.75 | C37: =NOV!C35+ 0.416666666666666 - COUNTIF(E37:AH37, "SL")-(COUNTIF(E37:AH37, "HDSL") * 0.5) -> 6.5833333
A38: SORIANO, MARY ANN VALLEJOS | B38: =NOV!B36 + 1.25 - (COUNTIF(E38:AH38, "VL") * 1) - (COUNTIF(E38:AH38, "HDL") * 0.5) -> 0.25 | C38: =NOV!C36+ 0.416666666666666 - COUNTIF(E38:AH38, "SL")-(COUNTIF(E38:AH38, "HDSL") * 0.5) -> 1.25 | G38: VL | H38: VL | M38: SL | X38: HDL | AE38: VL | AF38: VL
A39: TICSAY, CLAIROL | B39: =1.25*6- (COUNTIF(E39:AH39, "VL") * 1) - (COUNTIF(E39:AH39, "HDL") * 0.5) -> 4.5 | C39: =0.416666666666666*6 - COUNTIF(E39:AH39, "SL")-(COUNTIF(E39:AH39, "HDSL") * 0.5) -> 2.5 | AA39: VL | AB39: VL | AE39: VL | AI39: VL
A40: TRINIDAD, JENNIFER M | B40: =NOV!B37 + 1.25 - (COUNTIF(E40:AH40, "VL") * 1) - (COUNTIF(E40:AH40, "HDL") * 0.5) -> 9.25 | C40: =NOV!C37+ 0.416666666666666 - COUNTIF(E40:AH40, "SL")-(COUNTIF(E40:AH40, "HDSL") * 0.5) -> 0.083333333 | J40: VL | M40: SL | T40: SL | AA40: VL | AB40: VL | AE40: VL | AI40: VL

Sheet 2024
A1: NAME | D1: Leave Credits from YR 2023 | E1: YR 2024 TOTAL | F1: JAN 2024 | H1: FEB 2024 | J1: MAR.2024 | L1: APR.2024 | N1: MAY.2024 | P1: JUN.2024 | R1: JUL.2024 | T1: AUG.2024 | V1: SEPT.2024 | X1: OCT.2024 | Z1: NOV.2024 | AB1: DEC.2024 | AD1: REMAINING LEAVE (2024)
F2: Consumed | G2: Remaining | H2: Consumed | I2: Remaining | J2: Consumed | K2: Remaining | L2: Consumed | M2: Remaining | N2: Consumed | O2: Remaining | P2: Consumed | Q2: Remaining | R2: Consumed | S2: Remaining | T2: Consumed | U2: Remaining | V2: Consumed | W2: Remaining | X2: Consumed | Y2: Remaining | Z2: Consumed | AA2: Remaining | AB2: Consumed | AC2: Remaining
A3: ANTONIO, VINCENT KEVIN SANTOS
C4: Vacation Leave | D4: ='2023 ACCRUAL'!AE4 -> 11 | E4: 15 | F4: 6 | G4: =$E4/12-F4+D4 -> 6.25 | I4: =$E4/12+G4-H4 -> 7.5 | K4: =$E4/12+I4-J4 -> 8.75 | M4: =$E4/12+K4-L4 -> 10 | O4: =$E4/12+M4-N4 -> 11.25 | P4: 0 | Q4: =$E4/12+O4-P4 -> 12.5 | R4: 1 | S4: =$E4/12+Q4-R4 -> 12.75 | U4: =$E4/12+S4-T4 -> 14 | V4: 4 | W4: =$E4/12+U4-V4 -> 11.25 | Y4: =$E4/12+W4-X4 -> 12.5 | AA4: =$E4/12+Y4-Z4 -> 13.75 | AC4: =$E4/12+AA4-AB4 -> 15 | AD4: VL | AE4: =AC4 -> 15
C5: Sick Leave | D5: ='2023 ACCRUAL'!AE5 -> 5.68 | E5: 5 | F5: 1 | G5: =$E5/12-F5+D5 -> 5.0966667 | H5: 2 | I5: =$E5/12+G5-H5 -> 3.5133333 | J5: 1 | K5: =$E5/12+I5-J5 -> 2.93 | M5: =$E5/12+K5-L5 -> 3.3466667 | O5: =$E5/12+M5-N5 -> 3.7633333 | P5: 0 | Q5: =$E5/12+O5-P5 -> 4.18 | S5: =$E5/12+Q5-R5 -> 4.5966667 | U5: =$E5/12+S5-T5 -> 5.0133333 | W5: =$E5/12+U5-V5 -> 5.43 | Y5: =$E5/12+W5-X5 -> 5.8466667 | AA5: =$E5/12+Y5-Z5 -> 6.2633333 | AC5: =$E5/12+AA5-AB5 -> 6.68 | AD5: SL | AE5: =AC5 -> 6.68
A6: DELA CRUZ, SHAINA DIMAYUGO
C7: Vacation Leave | D7: ='2023 ACCRUAL'!AE7 -> 3 | E7: 15 | F7: 1 | G7: =$E7/12-F7+D7 -> 3.25 | I7: =$E7/12+G7-H7 -> 4.5 | K7: =$E7/12+I7-J7 -> 5.75 | L7: 1 | M7: =$E7/12+K7-L7 -> 6 | O7: =$E7/12+M7-N7 -> 7.25 | P7: 6 | Q7: =$E7/12+O7-P7 -> 2.5 | R7: 3 | S7: =$E7/12+Q7-R7 -> 0.75 | U7: =$E7/12+S7-T7 -> 2 | W7: =$E7/12+U7-V7 -> 3.25 | Y7: =$E7/12+W7-X7 -> 4.5 | AA7: =$E7/12+Y7-Z7 -> 5.75 | AC7: =$E7/12+AA7-AB7 -> 7 | AD7: VL | AE7: =AC7 -> 7
C8: Sick Leave | D8: ='2023 ACCRUAL'!AE8 -> 3.42 | E8: 5 | G8: =$E8/12-F8+D8 -> 3.8366667 | I8: =$E8/12+G8-H8 -> 4.2533333 | K8: =$E8/12+I8-J8 -> 4.67 | L8: 2 | M8: =$E8/12+K8-L8 -> 3.0866667 | N8: 1 | O8: =$E8/12+M8-N8 -> 2.5033333 | P8: 2 | Q8: =$E8/12+O8-P8 -> 0.92 | S8: =$E8/12+Q8-R8 -> 1.3366667 | U8: =$E8/12+S8-T8 -> 1.7533333 | V8: 1 | W8: =$E8/12+U8-V8 -> 1.17 | Y8: =$E8/12+W8-X8 -> 1.5866667 | AA8: =$E8/12+Y8-Z8 -> 2.0033333 | AC8: =$E8/12+AA8-AB8 -> 2.42 | AD8: SL | AE8: =AC8 -> 2.42
A9: JOSAFAT, RENALYN
C10: Vacation Leave | D10: ='2023 ACCRUAL'!AE10 -> 7 | E10: 15 | G10: =$E10/12-F10+D10 -> 8.25 | H10: 1 | I10: =$E10/12+G10-H10 -> 8.5 | K10: =$E10/12+I10-J10 -> 9.75 | M10: =$E10/12+K10-L10 -> 11 | N10: 1 | O10: =$E10/12+M10-N10 -> 11.25 | Q10: =$E10/12+O10-P10 -> 12.5 | R10: 1 | S10: =$E10/12+Q10-R10 -> 12.75 | T10: 1 | U10: =$E10/12+S10-T10 -> 13 | W10: =$E10/12+U10-V10 -> 14.25 | Y10: =$E10/12+W10-X10 -> 15.5 | AA10: =$E10/12+Y10-Z10 -> 16.75 | AC10: =$E10/12+AA10-AB10 -> 18 | AD10: VL | AE10: =AC10 -> 18
C11: Sick Leave | D11: ='2023 ACCRUAL'!AE11 -> -0.32 | E11: 5 | G11: =$E11/12-F11+D11 -> 0.096666667 | I11: =$E11/12+G11-H11 -> 0.51333333 | K11: =$E11/12+I11-J11 -> 0.93 | L11: 1 | M11: =$E11/12+K11-L11 -> 0.34666667 | O11: =$E11/12+M11-N11 -> 0.76333333 | P11: 1 | Q11: =$E11/12+O11-P11 -> 0.18 | S11: =$E11/12+Q11-R11 -> 0.59666667 | U11: =$E11/12+S11-T11 -> 1.0133333 | W11: =$E11/12+U11-V11 -> 1.43 | Y11: =$E11/12+W11-X11 -> 1.8466667 | AA11: =$E11/12+Y11-Z11 -> 2.2633333 | AC11: =$E11/12+AA11-AB11 -> 2.68 | AD11: SL | AE11: =AC11 -> 2.68
A12: GALGO, CEDRICK CRUZ
C13: Vacation Leave | D13: ='2023 ACCRUAL'!AE13 -> 12.5 | E13: 15 | F13: 3 | G13: =$E13/12-F13+D13 -> 10.75 | I13: =$E13/12+G13-H13 -> 12 | K13: =$E13/12+I13-J13 -> 13.25 | M13: =$E13/12+K13-L13 -> 14.5 | O13: =$E13/12+M13-N13 -> 15.75 | P13: 1 | Q13: =$E13/12+O13-P13 -> 16 | S13: =$E13/12+Q13-R13 -> 17.25 | U13: =$E13/12+S13-T13 -> 18.5 | W13: =$E13/12+U13-V13 -> 19.75 | Y13: =$E13/12+W13-X13 -> 21 | AA13: =$E13/12+Y13-Z13 -> 22.25 | AC13: =$E13/12+AA13-AB13 -> 23.5 | AD13: VL | AE13: =AC13 -> 23.5
C14: Sick Leave | D14: ='2023 ACCRUAL'!AE14 -> 4.68 | E14: 5 | G14: =$E14/12-F14+D14 -> 5.0966667 | I14: =$E14/12+G14-H14 -> 5.5133333 | K14: =$E14/12+I14-J14 -> 5.93 | M14: =$E14/12+K14-L14 -> 6.3466667 | O14: =$E14/12+M14-N14 -> 6.7633333 | Q14: =$E14/12+O14-P14 -> 7.18 | S14: =$E14/12+Q14-R14 -> 7.5966667 | U14: =$E14/12+S14-T14 -> 8.0133333 | W14: =$E14/12+U14-V14 -> 8.43 | Y14: =$E14/12+W14-X14 -> 8.8466667 | AA14: =$E14/12+Y14-Z14 -> 9.2633333 | AC14: =$E14/12+AA14-AB14 -> 9.68 | AD14: SL | AE14: =AC14 -> 9.68
A15: OTSUKA, SHIGERU CENTINA
C16: Vacation Leave | D16: ='2023 ACCRUAL'!AE16 -> 7.5 | E16: 15 | F16: 2 | G16: =$E16/12-F16+D16 -> 6.75 | I16: =$E16/12+G16-H16 -> 8 | K16: =$E16/12+I16-J16 -> 9.25 | L16: 2 | M16: =$E16/12+K16-L16 -> 8.5 | O16: =$E16/12+M16-N16 -> 9.75 | P16: 2 | Q16: =$E16/12+O16-P16 -> 9 | S16: =$E16/12+Q16-R16 -> 10.25 | U16: =$E16/12+S16-T16 -> 11.5 | W16: =$E16/12+U16-V16 -> 12.75 | Y16: =$E16/12+W16-X16 -> 14 | AA16: =$E16/12+Y16-Z16 -> 15.25 | AC16: =$E16/12+AA16-AB16 -> 16.5 | AD16: VL | AE16: =AC16 -> 16.5
C17: Sick Leave | D17: ='2023 ACCRUAL'!AE17 -> 2.68 | E17: 5 | F17: 1 | G17: =$E17/12-F17+D17 -> 2.0966667 | H17: 1 | I17: =$E17/12+G17-H17 -> 1.5133333 | K17: =$E17/12+I17-J17 -> 1.93 | M17: =$E17/12+K17-L17 -> 2.3466667 | N17: 1 | O17: =$E17/12+M17-N17 -> 1.7633333 | P17: 1 | Q17: =$E17/12+O17-P17 -> 1.18 | R17: 1 | S17: =$E17/12+Q17-R17 -> 0.59666667 | T17: 1 | U17: =$E17/12+S17-T17 -> 0.013333333 | W17: =$E17/12+U17-V17 -> 0.43 | Y17: =$E17/12+W17-X17 -> 0.84666667 | AA17: =$E17/12+Y17-Z17 -> 1.2633333 | AC17: =$E17/12+AA17-AB17 -> 1.68 | AD17: SL | AE17: =AC17 -> 1.68
A18: ALIMURONG, JOEL LUSUNG
C19: Vacation Leave | D19: ='2023 ACCRUAL'!AE19 -> 10.75 | E19: 15 | F19: 1 | G19: =$E19/12-F19+D19 -> 11 | I19: =$E19/12+G19-H19 -> 12.25 | K19: =$E19/12+I19-J19 -> 13.5 | M19: =$E19/12+K19-L19 -> 14.75 | N19: 1 | O19: =$E19/12+M19-N19 -> 15 | P19: 1 | Q19: =$E19/12+O19-P19 -> 15.25 | S19: =$E19/12+Q19-R19 -> 16.5 | U19: =$E19/12+S19-T19 -> 17.75 | W19: =$E19/12+U19-V19 -> 19 | Y19: =$E19/12+W19-X19 -> 20.25 | AA19: =$E19/12+Y19-Z19 -> 21.5 | AC19: =$E19/12+AA19-AB19 -> 22.75 | AD19: VL | AE19: =AC19 -> 22.75
C20: Sick Leave | D20: ='2023 ACCRUAL'!AE20 -> 6.26 | E20: 5 | G20: =$E20/12-F20+D20 -> 6.6766667 | I20: =$E20/12+G20-H20 -> 7.0933333 | K20: =$E20/12+I20-J20 -> 7.51 | M20: =$E20/12+K20-L20 -> 7.9266667 | O20: =$E20/12+M20-N20 -> 8.3433333 | P20: 1 | Q20: =$E20/12+O20-P20 -> 7.76 | S20: =$E20/12+Q20-R20 -> 8.1766667 | T20: 1 | U20: =$E20/12+S20-T20 -> 7.5933333 | W20: =$E20/12+U20-V20 -> 8.01 | Y20: =$E20/12+W20-X20 -> 8.4266667 | AA20: =$E20/12+Y20-Z20 -> 8.8433333 | AC20: =$E20/12+AA20-AB20 -> 9.26 | AD20: SL | AE20: =AC20 -> 9.26
A21: FERNANDEZ, FRANCIS EMMANUEL VELOSO
C22: Vacation Leave | D22: ='2023 ACCRUAL'!AE22 -> 9.25 | E22: 15 | F22: 1 | G22: =$E22/12-F22+D22 -> 9.5 | H22: 2 | I22: =$E22/12+G22-H22 -> 8.75 | J22: 1 | K22: =$E22/12+I22-J22 -> 9 | M22: =$E22/12+K22-L22 -> 10.25 | N22: 5 | O22: =$E22/12+M22-N22 -> 6.5 | Q22: =$E22/12+O22-P22 -> 7.75 | S22: =$E22/12+Q22-R22 -> 9 | U22: =$E22/12+S22-T22 -> 10.25 | W22: =$E22/12+U22-V22 -> 11.5 | Y22: =$E22/12+W22-X22 -> 12.75 | AA22: =$E22/12+Y22-Z22 -> 14 | AC22: =$E22/12+AA22-AB22 -> 15.25 | AD22: VL | AE22: =AC22 -> 15.25
C23: Sick Leave | D23: ='2023 ACCRUAL'!AE23 -> 1.26 | E23: 5 | F23: 2 | G23: =$E23/12-F23+D23 -> -0.32333333 | I23: =$E23/12+G23-H23 -> 0.093333333 | K23: =$E23/12+I23-J23 -> 0.51 | M23: =$E23/12+K23-L23 -> 0.92666667 | O23: =$E23/12+M23-N23 -> 1.3433333 | Q23: =$E23/12+O23-P23 -> 1.76 | S23: =$E23/12+Q23-R23 -> 2.1766667 | U23: =$E23/12+S23-T23 -> 2.5933333 | W23: =$E23/12+U23-V23 -> 3.01 | Y23: =$E23/12+W23-X23 -> 3.4266667 | AA23: =$E23/12+Y23-Z23 -> 3.8433333 | AC23: =$E23/12+AA23-AB23 -> 4.26 | AD23: SL | AE23: =AC23 -> 4.26
A24: CASTRO, AIZEL SANTOS
C25: Vacation Leave | D25: ='2023 ACCRUAL'!AE25 -> 13.25 | E25: 15 | F25: 2 | G25: =$E25/12-F25+D25 -> 12.5 | I25: =$E25/12+G25-H25 -> 13.75 | K25: =$E25/12+I25-J25 -> 15 | M25: =$E25/12+K25-L25 -> 16.25 | N25: 2 | O25: =$E25/12+M25-N25 -> 15.5 | Q25: =$E25/12+O25-P25 -> 16.75 | R25: 1 | S25: =$E25/12+Q25-R25 -> 17 | U25: =$E25/12+S25-T25 -> 18.25 | W25: =$E25/12+U25-V25 -> 19.5 | Y25: =$E25/12+W25-X25 -> 20.75 | AA25: =$E25/12+Y25-Z25 -> 22 | AC25: =$E25/12+AA25-AB25 -> 23.25 | AD25: VL | AE25: =AC25 -> 23.25
C26: Sick Leave | D26: ='2023 ACCRUAL'!AE26 -> -0.74 | E26: 5 | G26: =$E26/12-F26+D26 -> -0.32333333 | I26: =$E26/12+G26-H26 -> 0.093333333 | K26: =$E26/12+I26-J26 -> 0.51 | M26: =$E26/12+K26-L26 -> 0.92666667 | N26: 2 | O26: =$E26/12+M26-N26 -> -0.65666667 | Q26: =$E26/12+O26-P26 -> -0.24 | S26: =$E26/12+Q26-R26 -> 0.17666667 | U26: =$E26/12+S26-T26 -> 0.59333333 | V26: 1 | W26: =$E26/12+U26-V26 -> 0.01 | Y26: =$E26/12+W26-X26 -> 0.42666667 | AA26: =$E26/12+Y26-Z26 -> 0.84333333 | AC26: =$E26/12+AA26-AB26 -> 1.26 | AD26: SL | AE26: =AC26 -> 1.26
C27: Solo Parent Leave | E27: 7 | P27: 1 | Q27: =E27-P27 -> 6 | R27: 1 | S27: =Q27-R27 -> 5 | U27: =$E27/12+S27-T27 -> 5.5833333 | W27: =$E27/12+U27-V27 -> 6.1666667 | Y27: =$E27/12+W27-X27 -> 6.75 | AA27: =$E27/12+Y27-Z27 -> 7.3333333 | AC27: =$E27/12+AA27-AB27 -> 7.9166667 | AE27: =AC27 -> 7.9166667
A28: COLIS, REYMARK BRYAN SILVANO
C29: Vacation Leave | D29: ='2023 ACCRUAL'!AE28 -> 6.75 | E29: 15 | F29: 6 | G29: =$E29/12-F29+D29 -> 2 | H29: 1 | I29: =$E29/12+G29-H29 -> 2.25 | K29: =$E29/12+I29-J29 -> 3.5 | M29: =$E29/12+K29-L29 -> 4.75 | N29: 1 | O29: =$E29/12+M29-N29 -> 5 | P29: 1 | Q29: =$E29/12+O29-P29 -> 5.25 | S29: =$E29/12+Q29-R29 -> 6.5 | U29: =$E29/12+S29-T29 -> 7.75 | V29: 1 | W29: =$E29/12+U29-V29 -> 8 | Y29: =$E29/12+W29-X29 -> 9.25 | AA29: =$E29/12+Y29-Z29 -> 10.5 | AC29: =$E29/12+AA29-AB29 -> 11.75 | AD29: VL | AE29: =AC29 -> 11.75
C30: Sick Leave | D30: ='2023 ACCRUAL'!AE29 -> 6.26 | E30: 5 | G30: =$E30/12-F30+D30 -> 6.6766667 | I30: =$E30/12+G30-H30 -> 7.0933333 | K30: =$E30/12+I30-J30 -> 7.51 | M30: =$E30/12+K30-L30 -> 7.9266667 | O30: =$E30/12+M30-N30 -> 8.3433333 | Q30: =$E30/12+O30-P30 -> 8.76 | S30: =$E30/12+Q30-R30 -> 9.1766667 | U30: =$E30/12+S30-T30 -> 9.5933333 | W30: =$E30/12+U30-V30 -> 10.01 | Y30: =$E30/12+W30-X30 -> 10.426667 | AA30: =$E30/12+Y30-Z30 -> 10.843333 | AC30: =$E30/12+AA30-AB30 -> 11.26 | AD30: SL | AE30: =AC30 -> 11.26
A31: SARTHOU, IAN MICHAEL LOUIE ALEGA
C32: Vacation Leave | D32: ='2023 ACCRUAL'!AE31 -> 6.75 | E32: 15 | G32: =$E32/12-F32+D32 -> 8 | I32: =$E32/12+G32-H32 -> 9.25 | K32: =$E32/12+I32-J32 -> 10.5 | M32: =$E32/12+K32-L32 -> 11.75 | O32: =$E32/12+M32-N32 -> 13 | P32: 1 | Q32: =$E32/12+O32-P32 -> 13.25 | S32: =$E32/12+Q32-R32 -> 14.5 | U32: =$E32/12+S32-T32 -> 15.75 | W32: =$E32/12+U32-V32 -> 17 | Y32: =$E32/12+W32-X32 -> 18.25 | AA32: =$E32/12+Y32-Z32 -> 19.5 | AC32: =$E32/12+AA32-AB32 -> 20.75 | AD32: VL | AE32: =AC32 -> 20.75
C33: Sick Leave | D33: ='2023 ACCRUAL'!AE32 -> 4.5833333 | E33: 5 | G33: =$E33/12-F33+D33 -> 5 | I33: =$E33/12+G33-H33 -> 5.4166667 | K33: =$E33/12+I33-J33 -> 5.8333333 | M33: =$E33/12+K33-L33 -> 6.25 | N33: 1 | O33: =$E33/12+M33-N33 -> 5.6666667 | Q33: =$E33/12+O33-P33 -> 6.0833333 | S33: =$E33/12+Q33-R33 -> 6.5 | U33: =$E33/12+S33-T33 -> 6.9166667 | W33: =$E33/12+U33-V33 -> 7.3333333 | Y33: =$E33/12+W33-X33 -> 7.75 | AA33: =$E33/12+Y33-Z33 -> 8.1666667 | AC33: =$E33/12+AA33-AB33 -> 8.5833333 | AD33: SL | AE33: =AC33 -> 8.5833333
A34: RONQUILLO, RHEGENE INGAT | C34: Vacation Leave | D34: ='2023 ACCRUAL'!AE34 -> 7.25 | E34: 15 | F34: 4 | G34: =$E34/12-F34+D34 -> 4.5 | H34: 2 | I34: =$E34/12+G34-H34 -> 3.75 | K34: =$E34/12+I34-J34 -> 5 | M34: =$E34/12+K34-L34 -> 6.25 | N34: 3 | O34: =$E34/12+M34-N34 -> 4.5 | Q34: =$E34/12+O34-P34 -> 5.75 | S34: =$E34/12+Q34-R34 -> 7 | T34: 3 | U34: =$E34/12+S34-T34 -> 5.25 | W34: =$E34/12+U34-V34 -> 6.5 | Y34: =$E34/12+W34-X34 -> 7.75 | AA34: =$E34/12+Y34-Z34 -> 9 | AC34: =$E34/12+AA34-AB34 -> 10.25 | AD34: VL | AE34: =AC34 -> 10.25
C35: Sick Leave | D35: ='2023 ACCRUAL'!AE35 -> 2.75 | E35: 5 | G35: =$E35/12-F35+D35 -> 3.1666667 | I35: =$E35/12+G35-H35 -> 3.5833333 | K35: =$E35/12+I35-J35 -> 4 | M35: =$E35/12+K35-L35 -> 4.4166667 | O35: =$E35/12+M35-N35 -> 4.8333333 | P35: 1 | Q35: =$E35/12+O35-P35 -> 4.25 | S35: =$E35/12+Q35-R35 -> 4.6666667 | U35: =$E35/12+S35-T35 -> 5.0833333 | W35: =$E35/12+U35-V35 -> 5.5 | Y35: =$E35/12+W35-X35 -> 5.9166667 | AA35: =$E35/12+Y35-Z35 -> 6.3333333 | AC35: =$E35/12+AA35-AB35 -> 6.75 | AD35: SL | AE35: =AC35 -> 6.75
A36: SORIANO, MARY ANN VALLEJOS
C37: Vacation Leave | D37: ='2023 ACCRUAL'!AE37 -> 4.25 | E37: 15 | F37: 8 | G37: =$E37/12-F37+D37 -> -2.5 | H37: 1 | I37: =$E37/12+G37-H37 -> -2.25 | J37: 0.5 | K37: =$E37/12+I37-J37 -> -1.5 | M37: =$E37/12+K37-L37 -> -0.25 | N37: 2 | O37: =$E37/12+M37-N37 -> -1 | Q37: =$E37/12+O37-P37 -> 0.25 | S37: =$E37/12+Q37-R37 -> 1.5 | T37: 2 | U37: =$E37/12+S37-T37 -> 0.75 | W37: =$E37/12+U37-V37 -> 2 | Y37: =$E37/12+W37-X37 -> 3.25 | AA37: =$E37/12+Y37-Z37 -> 4.5 | AC37: =$E37/12+AA37-AB37 -> 5.75 | AD37: VL | AE37: =AC37 -> 5.75
C38: Sick Leave | D38: ='2023 ACCRUAL'!AE38 -> 3.75 | E38: 5 | G38: =$E38/12-F38+D38 -> 4.1666667 | I38: =$E38/12+G38-H38 -> 4.5833333 | K38: =$E38/12+I38-J38 -> 5 | M38: =$E38/12+K38-L38 -> 5.4166667 | O38: =$E38/12+M38-N38 -> 5.8333333 | Q38: =$E38/12+O38-P38 -> 6.25 | R38: 5 | S38: =$E38/12+Q38-R38 -> 1.6666667 | U38: =$E38/12+S38-T38 -> 2.0833333 | V38: 0.5 | W38: =$E38/12+U38-V38 -> 2 | Y38: =$E38/12+W38-X38 -> 2.4166667 | AA38: =$E38/12+Y38-Z38 -> 2.8333333 | AC38: =$E38/12+AA38-AB38 -> 3.25 | AD38: SL | AE38: =AC38 -> 3.25
A39: GATBONTON, BEVERLY TALOBAN
C40: Vacation Leave | D40: ='2023 ACCRUAL'!AE40 -> 5.75 | E40: 15 | F40: 3 | G40: =$E40/12-F40+D40 -> 4 | I40: =$E40/12+G40-H40 -> 5.25 | J40: 1 | K40: =$E40/12+I40-J40 -> 5.5 | L40: 1 | M40: =$E40/12+K40-L40 -> 5.75 | O40: =$E40/12+M40-N40 -> 7 | P40: 1 | Q40: =$E40/12+O40-P40 -> 7.25 | R40: 4 | S40: =$E40/12+Q40-R40 -> 4.5 | U40: =$E40/12+S40-T40 -> 5.75 | V40: 1 | W40: =$E40/12+U40-V40 -> 6 | Y40: =$E40/12+W40-X40 -> 7.25 | AA40: =$E40/12+Y40-Z40 -> 8.5 | AC40: =$E40/12+AA40-AB40 -> 9.75 | AD40: VL | AE40: =AC40 -> 9.75
...

Sheet OCT
A1: NAME | B1: VL | C1: SL | D1: SPL | E1: 45566 | F1: 45567 | G1: 45568 | H1: 45569 | I1: 45570 | J1: 45571 | K1: 45572 | L1: 45573 | M1: 45574 | N1: 45575 | O1: 45576 | P1: 45577 | Q1: 45578 | R1: 45579 | S1: 45580 | T1: 45581 | U1: 45582 | V1: 45583 | W1: 45584 | X1: 45585 | Y1: 45586 | Z1: 45587 | AA1: 45588 | AB1: 45589 | AC1: 45590 | AD1: 45591 | AE1: 45592 | AF1: 45593 | AG1: 45594 | AH1: 45595 | AI1: 45596
A2: AGAS, JILLIAN LAO | B2: ='2024'!W46 + 1.25 - (COUNTIF(E2:AI2, "VL") * 1) - (COUNTIF(E2:AI2, "HDL") * 0.5) -> 10.5 | C2: ='2024'!W47 + 0.416666666666666 - COUNTIF(E2:AI2, "SL") -> 0.5
A3: AGUILAR, IAN MYCO | B3: ='2024'!W52+1.25 - (COUNTIF(E3:AI3, "VL") * 1) - (COUNTIF(E3:AI3, "HDL") * 0.5) -> 15.5 | C3: ='2024'!W53+0.416666666666666- COUNTIF(E3:AI3, "SL") -> 1.5 | Y3: SL
A4: ALIMURONG, JOEL LUSUNG | B4: ='2024'!W19+1.25 -(COUNTIF(E4:AI4, "VL") * 1) - (COUNTIF(E4:AI4, "HDL") * 0.5) -> 19.25 | C4: ='2024'!W20+0.416666666666666- COUNTIF(E4:AI4, "SL") -> 8.4266667 | T4: VL
A5: ANTONIO, VINCENT KEVIN SANTOS | B5: ='2024'!W4+1.25 -(COUNTIF(E5:AI5, "VL") * 1) - (COUNTIF(E5:AI5, "HDL") * 0.5) -> 9 | C5: ='2024'!W5+0.416666666666666- COUNTIF(E5:AI5, "SL") -> 5.8466667 | U5: HDL | W5: VL | Y5: VL | AF5: VL
A6: AUSTRIA, LOUIS FERNAND BALUYOT | B6: =6.25+1.25 - (COUNTIF(E6:AI6, "VL") * 1) - (COUNTIF(E6:AI6, "HDL") * 0.5) -> 7.5 | C6: =2.08+0.416666666666666- COUNTIF(E6:AI6, "SL") -> 2.4966667
A7: BANSIL, KRISTIAN DAVID | B7: ='2024'!W85+1.25 - (COUNTIF(E7:AI7, "VL") * 1) - (COUNTIF(E7:AI7, "HDL") * 0.5) -> 10.25 | C7: ='2024'!W86+0.416666666666666- COUNTIF(E7:AI7, "SL") -> 1.75 | U7: VL | AF7: SL | AG7: SL
A8: BASILIO, ABIGAIL ANN Q | B8: ='2024'!W76+1.25 - (COUNTIF(E8:AI8, "VL") * 1) - (COUNTIF(E8:AI8, "HDL") * 0.5) -> 10.5 | C8: ='2024'!W77+0.416666666666666- COUNTIF(E8:AI8, "SL") -> 1.8333333
A9: BENALLA, RENNECA Villapaña | B9: ='2024'!W58+1.25 - (COUNTIF(E9:AI9, "VL") * 1) - (COUNTIF(E9:AI9, "HDL") * 0.5) -> 11 | C9: ='2024'!W59+0.416666666666666- COUNTIF(E9:AI9, "SL") -> 3.6666667 | O9: VL
A10: CAMERINO, YRIS GAELLE PARREÑAS | B10: =6.25+1.25 - (COUNTIF(E10:AI10, "VL") * 1) - (COUNTIF(E10:AI10, "HDL") * 0.5) -> 6.5 | C10: =2.08+0.416666666666666- COUNTIF(E10:AI10, "SL") -> 2.4966667 | T10: VL
A11: CASTRO, AIZEL SANTOS | B11: ='2024'!W25+1.25 - (COUNTIF(E11:AI11, "VL") * 1) - (COUNTIF(E11:AI11, "HDL") * 0.5) -> 18.75 | C11: ='2024'!W26+0.416666666666666- COUNTIF(E11:AI11, "SL") -> 0.42666667 | D11: ='2024'!W27- COUNTIF(E11:AI11, "SPL") -> 6.1666667 | S11: VL | T11: VL
A12: COLIS, REYMARK BRYAN SILVANO | B12: ='2024'!W29+0.125 - (COUNTIF(E12:AI12, "VL") * 1) - (COUNTIF(E12:AI12, "HDL") * 0.5) -> 8.125 | C12: ='2024'!W30+0.416666666666666- COUNTIF(E12:AI12, "SL") -> 8.4266667 | AB12: SL | AC12: SL
A13: CRISANTO, ELRITZ T | B13: ='2024'!W79+1.25 - (COUNTIF(E13:AI13, "VL") * 1) - (COUNTIF(E13:AI13, "HDL") * 0.5) -> 14.5 | C13: ='2024'!W80+0.416666666666666- COUNTIF(E13:AI13, "SL") -> 0.83333333 | AB13: SL
A14: DELA CRUZ, SHAINA DIMAYUGO | B14: =5+1.25 - (COUNTIF(E14:AI14, "VL") * 1) - (COUNTIF(E14:AI14, "HDL") * 0.5) -> 1.25 | C14: =1+0.416666666666666- COUNTIF(E14:AI14, "SL") -> 0.41666667 | E14: SL | F14: VL | G14: VL | H14: VL | I14: VL | J14: VL
A15: EMBUSCADO, EVER A | B15: ='2024'!W64+1.25 - (COUNTIF(E15:AI15, "VL") * 1) - (COUNTIF(E15:AI15, "HDL") * 0.5) -> 16.75 | C15: ='2024'!W65+0.416666666666666- COUNTIF(E15:AI15, "SL") -> 5.25
A16: FERNANDEZ, FRANCIS EMMANUEL VELOSO | B16: ='2024'!W22+1.25 - (COUNTIF(E16:AI16, "VL") * 1) - (COUNTIF(E16:AI16, "HDL") * 0.5) -> 12.75 | C16: ='2024'!W23+0.416666666666666- COUNTIF(E16:AI16, "SL") -> 1.4266667 | X16: SL | Y16: SL
A17: GALGO, CEDRICK CRUZ | B17: ='2024'!W13+1.25 - (COUNTIF(E17:AI17, "VL") * 1) - (COUNTIF(E17:AI17, "HDL") * 0.5) -> 21 | C17: ='2024'!W14+0.416666666666666- COUNTIF(E17:AI17, "SL") -> 8.8466667
A18: GATBONTON, ANALIZA TALOBAN | B18: ='2024'!W73+1.25 - (COUNTIF(E18:AI18, "VL") * 1) - (COUNTIF(E18:AI18, "HDL") * 0.5) -> 15.5 | C18: ='2024'!W74+0.416666666666666- COUNTIF(E18:AI18, "SL") -> 1.8333333 | E18: VL
A19: GATBONTON, BEVERLY TALOBAN | B19: ='2024'!W40+1.25 -(COUNTIF(E19:AI19, "VL") * 1) - (COUNTIF(E19:AI19, "HDL") * 0.5) -> 3.75 | C19: ='2024'!W41+0.416666666666666- COUNTIF(E19:AI19, "SL") -> 1.9166667 | E19: VL | H19: VL | T19: HDL | U19: HDL | AF19: LWOP | AH19: HDL
A20: JOSAFAT, RENALYN | B20: ='2024'!W10+1.25 - -(COUNTIF(E20:AI20, "VL") * 1) - (COUNTIF(E20:AI20, "HDL") * 0.5) -> 16.5 | C20: ='2024'!W11+0.416666666666666- COUNTIF(E20:AI20, "SL") -> 0.84666667 | J20: SL | AA20: VL
A21: MALINAO, ROGELIO DELA PENA | B21: ='2024'!W43+1.25 -(COUNTIF(E21:AI21, "VL") * 1) - (COUNTIF(E21:AI21, "HDL") * 0.5) -> 6.75 | C21: ='2024'!W44+0.416666666666666- COUNTIF(E21:AI21, "SL") -> 0.91666667 | S21: SL
A22: MATAGA, EDITH DAVID | B22: ='2024'!W55+1.25 - (COUNTIF(E22:AI22, "VL") * 1) - (COUNTIF(E22:AI22, "HDL") * 0.5) -> 1 | C22: ='2024'!W56+0.416666666666666- COUNTIF(E22:AI22, "SL") -> 0.66666667 | M22: HDL | O22: VL | AG22: HDL
A23: MENDOZA , SEAN JUSTINE F | B23: ='2024'!W70+1.25 - (COUNTIF(E23:AI23, "VL") * 1) - (COUNTIF(E23:AI23, "HDL") * 0.5) -> 9.75 | C23: ='2024'!W71+0.416666666666666- COUNTIF(E23:AI23, "SL") -> 4.25 | E23: VL | Y23: VL | Z23: VL | AA23: VL | AB23: SL | AC23: SL
A24: NAVALON, EVANEL CAACBAY | B24: ='2024'!W49+1.25 - (COUNTIF(E24:AI24, "VL") * 1) - (COUNTIF(E24:AI24, "HDL") * 0.5) -> 13.5 | C24: ='2024'!W50+0.416666666666666- COUNTIF(E24:AI24, "SL") -> 1.5 | L24: SL | N24: SL
A25: OCAMPO, ALFRED NAGUIT | B25: ='2024'!W61+1.25 - (COUNTIF(E25:AI25, "VL") * 1) - (COUNTIF(E25:AI25, "HDL") * 0.5) -> 9 | C25: ='2024'!W62+0.416666666666666- COUNTIF(E25:AI25, "SL") -> 3.6666667
A26: OTSUKA, SHIGERU CENTINA | B26: ='2024'!W16+1.25 - (COUNTIF(E26:AI26, "VL") * 1) - (COUNTIF(E26:AI26, "HDL") * 0.5) -> 11 | C26: ='2024'!W17+0.416666666666666- COUNTIF(E26:AI26, "SL") -> 0.84666667 | U26: VL | V26: VL | AC26: VL
A27: PABILLANO, FRANKLIN ROOS C | B27: ='2024'!W82+1.25 - (COUNTIF(E27:AI27, "VL") * 1) - (COUNTIF(E27:AI27, "HDL") * 0.5) -> 14 | C27: ='2024'!W83+0.416666666666666- COUNTIF(E27:AI27, "SL") -> 5
A28: PANGAN, CRISTINA MIRANDA | B28: =6.25+1.25 - (COUNTIF(E28:AI28, "VL") * 1) - (COUNTIF(E28:AI28, "HDL") * 0.5) -> 5.5 | C28: =2.08+0.416666666666666- COUNTIF(E28:AI28, "SL") -> 2.4966667 | G28: VL | R28: VL
A29: PINEDA, ERIKA SERIOSA | B29: =6.25+1.25 - (COUNTIF(E29:AI29, "VL") * 1) - (COUNTIF(E29:AI29, "HDL") * 0.5) -> 7.5 | C29: =2.08+0.416666666666666- COUNTIF(E29:AI29, "SL") -> 2.4966667
A30: RONQUILLO, RHEGENE INGAT | B30: ='2024'!W34+1.25 - (COUNTIF(E30:AI30, "VL") * 1) - (COUNTIF(E30:AI30, "HDL") * 0.5) -> 6.75 | C30: ='2024'!W35+0.416666666666666- COUNTIF(E30:AI30, "SL") -> 3.9166667 | E30: HDL | H30: SL | O30: HDL | R30: SL
A31: SARTHOU, IAN MICHAEL LOUIE ALEGA | B31: ='2024'!W32+1.25 - (COUNTIF(E31:AI31, "VL") * 1) - (COUNTIF(E31:AI31, "HDL") * 0.5) -> 18.25 | C31: ='2024'!W33+0.416666666666666- COUNTIF(E31:AI31, "SL") -> 5.75 | U31: SL | V31: SL
A32: SORIANO, MARY ANN VALLEJOS | B32: ='2024'!W37+1.25 - (COUNTIF(E32:AI32, "VL") * 1) - (COUNTIF(E32:AI32, "HDL") * 0.5) -> 2.25 | C32: ='2024'!W38+0.416666666666666- COUNTIF(E32:AI32, "SL") -> 2.4166667 | N32: VL
A33: TRINIDAD, JENNIFER M | B33: ='2024'!W67+1.25 - (COUNTIF(E33:AI33, "VL") * 1) - (COUNTIF(E33:AI33, "HDL") * 0.5) -> 18.75 | C33: ='2024'!W68+0.416666666666666- COUNTIF(E33:AI33, "SL") -> 1.25
A36: Samodio, Jhunel Carlo Traifalgar | B36: =1.25*6- (COUNTIF(E36:AI36, "VL") * 1) - (COUNTIF(E36:AI36, "HDL") * 0.5) -> 7.5 | C36: =0.416666666666666*6- COUNTIF(E36:AI36, "SL") -> 1.5 | W36: SL
A37: Gueco, Johana Rose Perez | B37: =1.25*6- (COUNTIF(E37:AI37, "VL") * 1) - (COUNTIF(E37:AI37, "HDL") * 0.5) -> 7.5 | C37: =0.416666666666666*6- COUNTIF(E37:AI37, "SL") -> 2.5 | D37: =7- COUNTIF(E37:AH37, "SPL") -> 5 | W37: SPL | AH37: SPL
A38: Lozano, Aldwin John | B38: =1.25*6- (COUNTIF(E38:AI38, "VL") * 1) - (COUNTIF(E38:AI38, "HDL") * 0.5) -> 6.5 | C38: =0.416666666666666*6- COUNTIF(E38:AI38, "SL") -> 1.5 | W38: VL | AA38: SL
A39: Austria, Louis Fernand B | B39: =1.25*6- (COUNTIF(E39:AI39, "VL") * 1) - (COUNTIF(E39:AI39, "HDL") * 0.5) -> 7.5 | C39: =0.416666666666666*6- COUNTIF(E39:AI39, "SL") -> 2.5
A40: Lozano, Aldwin John | B40: =1.25*6- (COUNTIF(E40:AI40, "VL") * 1) - (COUNTIF(E40:AI40, "HDL") * 0.5) -> 7.5 | C40: =0.416666666666666*6- COUNTIF(E40:AI40, "SL") -> 2.5
A41: Camerino, Yris Gaelle P. | B41: =1.25*6- (COUNTIF(E41:AI41, "VL") * 1) - (COUNTIF(E41:AI41, "HDL") * 0.5) -> 7.5 | C41: =0.416666666666666*6- COUNTIF(E41:AI41, "SL") -> 2.5

Sheet NOV
A1: NAME | B1: VL | C1: SL | D1: SPL | E1: 45597 | F1: 45598 | G1: 45599 | H1: 45600 | I1: 45601 | J1: 45602 | K1: 45603 | L1: 45604 | M1: 45605 | N1: 45606 | O1: 45607 | P1: 45608 | Q1: 45609 | R1: 45610 | S1: 45611 | T1: 45612 | U1: 45613 | V1: 45614 | W1: 45615 | X1: 45616 | Y1: 45617 | Z1: 45618 | AA1: 45619 | AB1: 45620 | AC1: 45621 | AD1: 45622 | AE1: 45623 | AF1: 45624 | AG1: 45625 | AH1: 45626
A2: AGAS, JILLIAN LAO | B2: =OCT!B2 + 1.25 - (COUNTIF(E2:AH2, "VL") * 1) - (COUNTIF(E2:AH2, "HDL") * 0.5) -> 9.75 | C2: =OCT!C2+ 0.416666666666666 - COUNTIF(E2:AH2, "SL") -> 0.91666667 | M2: VL | P2: VL
A3: AGUILAR, IAN MYCO | B3: =OCT!B3 + 1.25 - (COUNTIF(E3:AH3, "VL") * 1) - (COUNTIF(E3:AH3, "HDL") * 0.5) -> 16.75 | C3: =OCT!C3+ 0.416666666666666 - COUNTIF(E3:AH3, "SL") -> 0.91666667 | H3: SL
A4: ALIMURONG, JOEL LUSUNG | B4: =OCT!B4 + 1.25 - (COUNTIF(E4:AH4, "VL") * 1) - (COUNTIF(E4:AH4, "HDL") * 0.5) -> 20.5 | C4: =OCT!C4+ 0.416666666666666 - COUNTIF(E4:AH4, "SL") -> 7.8433333 | I4: SL
A5: ANTONIO, VINCENT KEVIN SANTOS | B5: =OCT!B5 + 1.25 - (COUNTIF(E5:AH5, "VL") * 1) - (COUNTIF(E5:AH5, "HDL") * 0.5) -> 9.25 | C5: =OCT!C5+ 0.416666666666666 - COUNTIF(E5:AH5, "SL") -> 5.2633333 | V5: VL | W5: SL
A6: AUSTRIA, LOUIS FERNAND BALUYOT | B6: =OCT!B39+1.25- (COUNTIF(E6:AH6, "VL") * 1) - (COUNTIF(E6:AH6, "HDL") * 0.5) -> 8.75 | C6: =OCT!C39+0.416666666666666- COUNTIF(E6:AH6, "SL") -> 2.9166667
A7: BACONGALLO, NIKA NUEVA | B7: =1.25*6- (COUNTIF(E7:AH7, "VL") * 1) - (COUNTIF(E7:AH7, "HDL") * 0.5) -> 7.5 | C7: =0.416666666666666*6- COUNTIF(E7:AH7, "SL") -> 1.5 | S7: SL
A8: BANSIL, KRISTIAN DAVID | B8: ='2024'!W85+1.25 - (COUNTIF(E8:AH8, "VL") * 1) - (COUNTIF(E8:AH8, "HDL") * 0.5) -> 11.25 | C8: ='2024'!W86+0.416666666666666- COUNTIF(E8:AH8, "SL") -> 3.75
A9: BENALLA, RENNECA Villapaña | B9: ='2024'!W58+1.25 - (COUNTIF(E9:AH9, "VL") * 1) - (COUNTIF(E9:AH9, "HDL") * 0.5) -> 11 | C9: ='2024'!W59+0.416666666666666- COUNTIF(E9:AH9, "SL") -> 3.6666667 | O9: VL
A10: CAMERINO, YRIS GAELLE PARREÑAS | B10: =OCT!B41+1.25 - (COUNTIF(E10:AH10, "VL") * 1) - (COUNTIF(E10:AH10, "HDL") * 0.5) -> 8.75 | C10: =OCT!C41+0.416666666666666- COUNTIF(E10:AH10, "SL") -> 1.9166667 | Y10: SL
A11: CASTRO, AIZEL SANTOS | B11: =OCT!B11+1.25 - (COUNTIF(E11:AH11, "VL") * 1) - (COUNTIF(E11:AH11, "HDL") * 0.5) -> 13 | C11: =OCT!C11+0.416666666666666- COUNTIF(E11:AH11, "SL") -> -0.15666667 | D11: =OCT!D11- COUNTIF(E11:AH11, "SPL") -> 6.1666667 | J11: SL | L11: VL | O11: VL | P11: VL | Q11: VL | R11: VL | S11: VL | V11: VL
A12: CASTILLANO, DENVER ORLANDA | B12: =1.25*5 - (COUNTIF(E12:AH12, "VL") * 1) - (COUNTIF(E12:AH12, "HDL") * 0.5) -> 6.25 | C12: =0.416666666666666*5- COUNTIF(E12:AH12, "SL") -> 2.0833333
A13: COLIS, REYMARK BRYAN SILVANO | B13: =OCT!B12+1.25 - (COUNTIF(E13:AH13, "VL") * 1) - (COUNTIF(E13:AH13, "HDL") * 0.5) -> 6.375 | C13: =OCT!C12+0.416666666666666- COUNTIF(E13:AH13, "SL") -> 8.8433333 | V13: VL | W13: VL | X13: VL
A14: CRISANTO, ELRITZ T | B14: =OCT!B13+1.25 - (COUNTIF(E14:AH14, "VL") * 1) - (COUNTIF(E14:AH14, "HDL") * 0.5) -> 14.75 | C14: =OCT!C13+0.416666666666666- COUNTIF(E14:AH14, "SL") -> 1.25 | AC14: VL
A15: DELA CRUZ, SHAINA DIMAYUGO | B15: =OCT!B14+1.25 - (COUNTIF(E15:AH15, "VL") * 1) - (COUNTIF(E15:AH15, "HDL") * 0.5) -> 2.5 | C15: =OCT!C14+0.416666666666666- COUNTIF(E15:AH15, "SL") -> 0.83333333
A16: EMBUSCADO, EVER A | B16: =OCT!B15+1.25 - (COUNTIF(E16:AH16, "VL") * 1) - (COUNTIF(E16:AH16, "HDL") * 0.5) -> 18 | C16: =OCT!C15+0.416666666666666- COUNTIF(E16:AH16, "SL") -> 5.6666667
A17: FERNANDEZ, FRANCIS EMMANUEL VELOSO | B17: =OCT!B16+1.25 - (COUNTIF(E17:AH17, "VL") * 1) - (COUNTIF(E17:AH17, "HDL") * 0.5) -> 14 | C17: =OCT!C16+0.416666666666666- COUNTIF(E17:AH17, "SL") -> 1.8433333
A18: GALGO, CEDRICK CRUZ | B18: =OCT!B17+1.25 - (COUNTIF(E18:AH18, "VL") * 1) - (COUNTIF(E18:AH18, "HDL") * 0.5) -> 22.25 | C18: =OCT!C17+0.416666666666666- COUNTIF(E18:AH18, "SL") -> 9.2633333
A19: GATBONTON, ANALIZA TALOBAN | B19: =OCT!B18+1.25 - (COUNTIF(E19:AH19, "VL") * 1) - (COUNTIF(E19:AH19, "HDL") * 0.5) -> 13.75 | C19: =OCT!C18+0.416666666666666- COUNTIF(E19:AH19, "SL") -> 2.25 | R19: VL | S19: VL | AG19: VL
A20: GATBONTON, BEVERLY TALOBAN | B20: =OCT!B19+1.25 -(COUNTIF(E20:AH20, "VL") * 1) - (COUNTIF(E20:AH20, "HDL") * 0.5) -> 3 | C20: =OCT!C19+0.416666666666666- COUNTIF(E20:AH20, "SL") -> 0.33333333 | J20: SL | L20: SL | R20: VL | S20: VL
A21: GUECO, JOHANA ROSE PEREZ | B21: =OCT!B37+1.25 -(COUNTIF(E21:AH21, "VL") * 1) - (COUNTIF(E21:AH21, "HDL") * 0.5) -> 6.75 | C21: =OCT!C37+0.416666666666666- COUNTIF(E21:AH21, "SL") -> 2.9166667 | D21: =OCT!D37- COUNTIF(E21:AH21, "SPL") -> 3 | P21: SPL | Q21: SPL | Y21: VL | Z21: VL
A22: JOSAFAT, RENALYN | B22: =OCT!B20+1.25 -(COUNTIF(E22:AH22, "VL") * 1) - (COUNTIF(E22:AH22, "HDL") * 0.5) -> 9.75 | C22: =OCT!C20+0.416666666666666- COUNTIF(E22:AH22, "SL") -> 0.26333333 | I22: VL | Q22: VL | Y22: VL | Z22: VL | AC22: VL | AD22: VL | AE22: VL | AF22: VL | AG22: SL
A23: LOZANO, ALDWIN JOHN | B23: =OCT!B38+1.25 - -(COUNTIF(E23:AH23, "VL") * 1) - (COUNTIF(E23:AH23, "HDL") * 0.5) -> 7.75 | C23: =OCT!C38+0.416666666666666- COUNTIF(E23:AH23, "SL") -> 1.9166667
A24: MALINAO, ROGELIO DELA PENA | B24: =OCT!B21+1.25 -(COUNTIF(E24:AH24, "VL") * 1) - (COUNTIF(E24:AH24, "HDL") * 0.5) -> 7 | C24: =OCT!C21+0.416666666666666- COUNTIF(E24:AH24, "SL") -> 1.3333333 | AC24: VL
A25: MATAGA, EDITH DAVID | B25: =OCT!B22+1.25 - (COUNTIF(E25:AH25, "VL") * 1) - (COUNTIF(E25:AH25, "HDL") * 0.5) -> 0.25 | C25: =OCT!C22+0.416666666666666- COUNTIF(E25:AH25, "SL") -> 0.083333333 | L25: VL | Q25: HDL | R25: SL | S25: HDL
A26: MENDOZA , SEAN JUSTINE F | B26: =OCT!B23+1.25 - (COUNTIF(E26:AH26, "VL") * 1) - (COUNTIF(E26:AH26, "HDL") * 0.5) -> 11 | C26: =OCT!C23+0.416666666666666- COUNTIF(E26:AH26, "SL") -> 3.6666667 | P26: SL
A27: NAVALON, EVANEL CAACBAY | B27: =OCT!B24+1.25 - (COUNTIF(E27:AH27, "VL") * 1) - (COUNTIF(E27:AH27, "HDL") * 0.5) -> 14.75 | C27: =OCT!C24+0.416666666666666- COUNTIF(E27:AH27, "SL") -> 0.91666667 | AF27: SL
A28: OCAMPO, ALFRED NAGUIT | B28: =OCT!B25+1.25 - (COUNTIF(E28:AH28, "VL") * 1) - (COUNTIF(E28:AH28, "HDL") * 0.5) -> 10.25 | C28: =OCT!C25+0.416666666666666- COUNTIF(E28:AH28, "SL") -> 4.0833333
A29: OTSUKA, SHIGERU CENTINA | B29: =OCT!B26+1.25 - (COUNTIF(E29:AH29, "VL") * 1) - (COUNTIF(E29:AH29, "HDL") * 0.5) -> 11.25 | C29: =OCT!C26+0.416666666666666- COUNTIF(E29:AH29, "SL") -> 1.2633333 | V29: VL
A30: PABILLANO, FRANKLIN ROOS C | B30: =OCT!B27+1.25 - (COUNTIF(E30:AH30, "VL") * 1) - (COUNTIF(E30:AH30, "HDL") * 0.5) -> 15.25 | C30: =OCT!C27+0.416666666666666- COUNTIF(E30:AH30, "SL") -> 5.4166667
A31: PANGAN, CRISTINA MIRANDA | B31: =OCT!B28+1.25 - (COUNTIF(E31:AH31, "VL") * 1) - (COUNTIF(E31:AH31, "HDL") * 0.5) -> 6.75 | C31: =OCT!C28+0.416666666666666- COUNTIF(E31:AH31, "SL") -> 2.9133333
A32: PINEDA, ERIKA SERIOSA | B32: =OCT!B29+1.25 - (COUNTIF(E32:AH32, "VL") * 1) - (COUNTIF(E32:AH32, "HDL") * 0.5) -> 3.75 | C32: =OCT!C29+0.416666666666666- COUNTIF(E32:AH32, "SL") -> 2.9133333 | AC32: VL | AD32: VL | AE32: VL | AF32: VL | AG32: VL
A33: RONQUILLO, RHEGENE INGAT | B33: =OCT!B30+1.25 - (COUNTIF(E33:AH33, "VL") * 1) - (COUNTIF(E33:AH33, "HDL") * 0.5) -> 8 | C33: =OCT!C30+0.416666666666666- COUNTIF(E33:AH33, "SL") -> 3.3333333 | AC33: SL
A34: SAMODIO, JHUNEL CARLO TRAIFALGAR | B34: =OCT!B36+1.25 - (COUNTIF(E34:AH34, "VL") * 1) - (COUNTIF(E34:AH34, "HDL") * 0.5) -> 8.75 | C34: =OCT!C36+0.416666666666666- COUNTIF(E34:AH34, "SL") -> 0.91666667 | Q34: SL
A35: SARTHOU, IAN MICHAEL LOUIE ALEGA | B35: =OCT!B31+1.25 - (COUNTIF(E35:AH35, "VL") * 1) - (COUNTIF(E35:AH35, "HDL") * 0.5) -> 19.5 | C35: =OCT!C31+0.416666666666666- COUNTIF(E35:AH35, "SL") -> 6.1666667
A36: SORIANO, MARY ANN VALLEJOS | B36: =OCT!B32+1.25 - (COUNTIF(E36:AH36, "VL") * 1) - (COUNTIF(E36:AH36, "HDL") * 0.5) -> 3.5 | C36: =OCT!C32+0.416666666666666- COUNTIF(E36:AH36, "SL") -> 1.8333333 | T36: SL
A37: TRINIDAD, JENNIFER M | B37: =OCT!B33+1.25 - (COUNTIF(E37:AH37, "VL") * 1) - (COUNTIF(E37:AH37, "HDL") * 0.5) -> 12 | C37: =OCT!C33+0.416666666666666- COUNTIF(E37:AH37, "SL") -> 1.6666667 | J37: VL | Y37: VL | Z37: VL | AC37: VL | AD37: VL | AE37: VL | AF37: VL | AG37: VL

Sheet Jan2025
